Workbook

Sheet Guide
B1: SaaS Financial Model - how it works
B3: WHAT IT DOES
B4: A 36-month model of a subscription software business with three plans (Basic, Pro, Enterprise).
B5: It turns a handful of drivers (price, customer adds, churn, CAC, costs) into MRR/ARR, an income statement, a cash flow statement and unit economics.
B7: HOW THE TABS CONNECT
B8: 1. Assumptions - every input lives here. Change a blue number and the whole model updates.
B9: 2. Revenue Build - per plan: customers (beginning + new - churned = ending) and the MRR bridge (beginning + new + expansion - churn = ending).
B10: 3. Income Statement - revenue, cost of revenue, gross profit, opex (S&M, R&D, G&A), EBITDA, D&A, taxes, net income.
B11: 4. Cash Flow - net income + D&A - increase in receivables - capex + equity raised = change in cash; burn and runway.
B12: 5. Annual Summary - yearly roll-up, KPIs (ARR growth, margins, CAC, LTV, LTV/CAC, payback, Rule of 40) and charts.
B14: COLOR CODE
B15: Blue text = hard-coded input you can change | Black = formula | Green = link to another tab | Yellow fill = key driver
... B25: Annual prepaid plans + deferred revenue; headcount-driven opex; NOL tracking; cohort retention curves; a balance sheet; scenario switch (base/bull/bear).

Sheet Annual Summary
A1: Annual Summary & KPIs
B3: Start (M0) | C3: 1 | D3: 2 | E3: 3 | F3: How it's calculated
A4: Growth
A5: Ending customers | B5: ='Revenue Build'!B42 -> 133 | C5: =INDEX('Revenue Build'!$C$42:$AL$42,C$3*12) -> 891.85054 | D5: =INDEX('Revenue Build'!$C$42:$AL$42,D$3*12) -> 2071.0585 | E5: =INDEX('Revenue Build'!$C$42:$AL$42,E$3*12) -> 4052.7412 | F5: Month-12/24/36 balance
A6: Ending MRR | B6: ='Revenue Build'!B47 -> 13867 | C6: =INDEX('Revenue Build'!$C$47:$AL$47,C$3*12) -> 114908.37 | D6: =INDEX('Revenue Build'!$C$47:$AL$47,D$3*12) -> 280992.33 | E6: =INDEX('Revenue Build'!$C$47:$AL$47,E$3*12) -> 562555.45 | F6: Monthly recurring revenue at year end
A7: Ending ARR | B7: =B6*12 -> 166404 | C7: =C6*12 -> 1378900.5 | D7: =D6*12 -> 3371908 | E7: =E6*12 -> 6750665.3 | F7: MRR x 12
A8: ARR growth (%) | C8: =IF(B7>0,C7/B7-1,0) -> 7.2864623 | D8: =IF(C7>0,D7/C7-1,0) -> 1.4453599 | E8: =IF(D7>0,E7/D7-1,0) -> 1.0020313 | F8: vs. prior year-end (Year 1 vs. Month 0)
A9: Revenue | C9: =SUMIFS('Income Statement'!$C$5:$AL$5,'Income Statement'!$C$3:$AL$3,C$3) -> 725481.44 | D9: =SUMIFS('Income Statement'!$C$5:$AL$5,'Income Statement'!$C$3:$AL$3,D$3) -> 2290722.7 | E9: =SUMIFS('Income Statement'!$C$5:$AL$5,'Income Statement'!$C$3:$AL$3,E$3) -> 4911898 | F9: Sum of monthly recognized revenue
A10: Revenue growth (%) | C10: ="n/a" -> n/a | D10: =IF(C9>0,D9/C9-1,0) -> 2.1575208 | E10: =IF(D9>0,E9/D9-1,0) -> 1.1442569 | F10: Year-over-year
A11: Profitability
A12: Gross profit | C12: =SUMIFS('Income Statement'!$C$11:$AL$11,'Income Statement'!$C$3:$AL$3,C$3) -> 569749.83 | D12: =SUMIFS('Income Statement'!$C$11:$AL$11,'Income Statement'!$C$3:$AL$3,D$3) -> 1809449.8 | E12: =SUMIFS('Income Statement'!$C$11:$AL$11,'Income Statement'!$C$3:$AL$3,E$3) -> 3889658.4
A13: Gross margin (%) | C13: =IF(C9<>0,C12/C9,0) -> 0.78534033 | D13: =IF(D9<>0,D12/D9,0) -> 0.78990346 | E13: =IF(E9<>0,E12/E9,0) -> 0.79188502 | F13: SaaS benchmark: 70-80%+
A14: EBITDA | C14: =SUMIFS('Income Statement'!$C$18:$AL$18,'Income Statement'!$C$3:$AL$3,C$3) -> -1619545.6 | D14: =SUMIFS('Income Statement'!$C$18:$AL$18,'Income Statement'!$C$3:$AL$3,D$3) -> -1226904.1 | E14: =SUMIFS('Income Statement'!$C$18:$AL$18,'Income Statement'!$C$3:$AL$3,E$3) -> -506885.03
A15: EBITDA margin (%) | C15: =IF(C9<>0,C14/C9,0) -> -2.2323736 | D15: =IF(D9<>0,D14/D9,0) -> -0.53559692 | E15: =IF(E9<>0,E14/E9,0) -> -0.10319535
A16: Net income | C16: =SUMIFS('Income Statement'!$C$23:$AL$23,'Income Statement'!$C$3:$AL$3,C$3) -> -1630379 | D16: =SUMIFS('Income Statement'!$C$23:$AL$23,'Income Statement'!$C$3:$AL$3,D$3) -> -1257737.4 | E16: =SUMIFS('Income Statement'!$C$23:$AL$23,'Income Statement'!$C$3:$AL$3,E$3) -> -557718.36
A17: Cash
A18: Free cash flow | C18: =SUMIFS('Cash Flow'!$C$22:$AL$22,'Cash Flow'!$C$3:$AL$3,C$3) -> -1775391.1 | D18: =SUMIFS('Cash Flow'!$C$22:$AL$22,'Cash Flow'!$C$3:$AL$3,D$3) -> -1449500.4 | E18: =SUMIFS('Cash Flow'!$C$22:$AL$22,'Cash Flow'!$C$3:$AL$3,E$3) -> -842293.01 | F18: CFO + capex
A19: Ending cash | B19: ='Cash Flow'!B19 -> 2000000 | C19: =INDEX('Cash Flow'!$C$19:$AL$19,C$3*12) -> 224608.87 | D19: =INDEX('Cash Flow'!$C$19:$AL$19,D$3*12) -> 1775108.5 | E19: =INDEX('Cash Flow'!$C$19:$AL$19,E$3*12) -> 932815.47
A20: Lowest month-end cash in year | C20: =_xlfn.MINIFS('Cash Flow'!$C$19:$AL$19,'Cash Flow'!$C$3:$AL$3,C$3) -> 224608.87 | D20: =_xlfn.MINIFS('Cash Flow'!$C$19:$AL$19,'Cash Flow'!$C$3:$AL$3,D$3) -> 1775108.5 | E20: =_xlfn.MINIFS('Cash Flow'!$C$19:$AL$19,'Cash Flow'!$C$3:$AL$3,E$3) -> 932815.47 | F20: Must stay above zero - tells you when you need to raise
A21: Unit economics
A22: New customers acquired | C22: =SUMIFS('Revenue Build'!$C$40:$AL$40,'Revenue Build'!$C$3:$AL$3,C$3) -> 905.49357 | D22: =SUMIFS('Revenue Build'!$C$40:$AL$40,'Revenue Build'!$C$3:$AL$3,D$3) -> 1620.2816 | E22: =SUMIFS('Revenue Build'!$C$40:$AL$40,'Revenue Build'!$C$3:$AL$3,E$3) -> 2900.4192
A23: Sales & marketing spend | C23: =-SUMIFS('Income Statement'!$C$14:$AL$14,'Income Statement'!$C$3:$AL$3,C$3) -> 1089760.2 | D23: =-SUMIFS('Income Statement'!$C$14:$AL$14,'Income Statement'!$C$3:$AL$3,D$3) -> 1743541.3 | E23: =-SUMIFS('Income Statement'!$C$14:$AL$14,'Income Statement'!$C$3:$AL$3,E$3) -> 2875411.2
A24: Blended CAC ($ per new customer) | C24: =IF(C22>0,C23/C22,0) -> 1203.4985 | D24: =IF(D22>0,D23/D22,0) -> 1076.073 | E24: =IF(E22>0,E23/E22,0) -> 991.37779 | F24: Total S&M / new customers (includes fixed marketing)
A25: Avg monthly logo churn (%) | C25: =IF(SUMIFS('Revenue Build'!$C$39:$AL$39,'Revenue Build'!$C$3:$AL$3,C$3)>0,-SUMIFS('Revenue Build'!$C$41:$AL$41,'Revenue Build'!$C$3:$AL$3,C$3)/SUMIFS('Revenue Build'!$C$39:$AL$39,'Revenue Build'!$C$3:$AL$3,C$3),0) -> 0.026738945 | D25: =IF(SUMIFS('Revenue Build'!$C$39:$AL$39,'Revenue Build'!$C$3:$AL$3,D$3)>0,-SUMIFS('Revenue Build'!$C$41:$AL$41,'Revenue Build'!$C$3:$AL$3,D$3)/SUMIFS('Revenue Build'!$C$39:$AL$39,'Revenue Build'!$C$3:$AL$3,D$3),0) -> 0.026541186 | E25: =IF(SUMIFS('Revenue Build'!$C$39:$AL$39,'Revenue Build'!$C$3:$AL$3,E$3)>0,-SUMIFS('Revenue Build'!$C$41:$AL$41,'Revenue Build'!$C$3:$AL$3,E$3)/SUMIFS('Revenue Build'!$C$39:$AL$39,'Revenue Build'!$C$3:$AL$3,E$3),0) -> 0.026483413 | F25: Churned customers / beginning customers, summed over the year
A26: ARPA ($ / month, year end) | C26: =IF(C5>0,C6/C5,0) -> 128.84263 | D26: =IF(D5>0,D6/D5,0) -> 135.67571 | E26: =IF(E5>0,E6/E5,0) -> 138.80863
A27: Customer lifetime value (LTV) | C27: =IF(C25>0,C26*C13/C25,0) -> 3784.1925 | D27: =IF(D25>0,D26*D13/D25,0) -> 4037.9021 | E27: =IF(E25>0,E26*E13/E25,0) -> 4150.5403 | F27: ARPA x gross margin / monthly churn
A28: LTV / CAC | C28: =IF(C24>0,C27/C24,0) -> 3.1443266 | D28: =IF(D24>0,D27/D24,0) -> 3.7524426 | E28: =IF(E24>0,E27/E24,0) -> 4.1866383 | F28: Healthy SaaS: 3.0x or higher
A29: CAC payback (months) | C29: =IF(C26*C13>0,C24/(C26*C13),0) -> 11.894004 | D29: =IF(D26*D13>0,D24/(D26*D13),0) -> 10.040738 | E29: =IF(E26*E13>0,E24/(E26*E13),0) -> 9.0190459 | F29: Months of gross profit to earn back CAC. Good: < 12-18
A30: Net MRR churn (monthly, %) | C30: =IF(SUMIFS('Revenue Build'!$C$43:$AL$43,'Revenue Build'!$C$3:$AL$3,C$3)>0,-(SUMIFS('Revenue Build'!$C$46:$AL$46,'Revenue Build'!$C$3:$AL$3,C$3)+SUMIFS('Revenue Build'!$C$45:$AL$45,'Revenue Build'!$C$3:$AL$3,C$3))/SUMIFS('Revenue Build'!$C$43:$AL$43,'Revenue Build'!$C$3:$AL$3,C$3),0) -> 0.011393815 | D30: =IF(SUMIFS('Revenue Build'!$C$43:$AL$43,'Revenue Build'!$C$3:$AL$3,D$3)>0,-(SUMIFS('Revenue Build'!$C$46:$AL$46,'Revenue Build'!$C$3:$AL$3,D$3)+SUMIFS('Revenue Build'!$C$45:$AL$45,'Revenue Build'!$C$3:$AL$3,D$3))/SUMIFS('Revenue Build'!$C$43:$AL$43,'Revenue Build'!$C$3:$AL$3,D$3),0) -> 0.010569336 | E30: =IF(SUMIFS('Revenue Build'!$C$43:$AL$43,'Revenue Build'!$C$3:$AL$3,E$3)>0,-(SUMIFS('Revenue Build'!$C$46:$AL$46,'Revenue Build'!$C$3:$AL$3,E$3)+SUMIFS('Revenue Build'!$C$45:$AL$45,'Revenue Build'!$C$3:$AL$3,E$3))/SUMIFS('Revenue Build'!$C$43:$AL$43,'Revenue Build'!$C$3:$AL$3,E$3),0) -> 0.010320332 | F30: (Churned MRR - expansion MRR) / beginning MRR. Negative = net expansion
A31: Rule of 40 (%) | C31: ="n/a" -> n/a | D31: =D10+D15 -> 1.6219239 | E31: =E10+E15 -> 1.0410615 | F31: Revenue growth + EBITDA margin. >= 40% is strong

Sheet Assumptions
A1: Assumptions
A2: Blue = input (change freely). Yellow = key driver. All values are illustrative, set by the modeller - not company data.
A4: Plan assumptions | B4: Basic | C4: Pro | D4: Enterprise | E4: Notes
A5: Monthly price ($ per customer / month) | B5: 49 | C5: 199 | D5: 999 | E5: List price per account
A6: New customers acquired in Month 1 | B6: 40 | C6: 15 | D6: 2 | E6: Gross new logos in the first forecast month
A7: Monthly growth in new customer adds (%) | B7: 0.05 | C7: 0.05 | D7: 0.04 | E7: Compounds: adds in month t = Month 1 adds x (1+g)^(t-1)
A8: Monthly logo churn (%) | B8: 0.03 | C8: 0.02 | D8: 0.01 | E8: % of beginning customers (and MRR) lost each month
A9: Starting customers (Month 0) | B9: 100 | C9: 30 | D9: 3 | E9: Existing base at model start
A10: Monthly expansion (% of beginning MRR) | B10: 0 | C10: 0.01 | D10: 0.015 | E10: Upsell / extra seats from existing customers
A11: CAC - cost to acquire one customer ($) | B11: 300 | C11: 1500 | D11: 12000 | E11: Variable sales & marketing cost per new logo
A13: Operating cost assumptions | B13: Value | E13: Notes
A14: Hosting & infrastructure (% of revenue) | B14: 0.12 | E14: Cloud cost scales with usage/revenue
A15: Payment processing fees (% of revenue) | B15: 0.03 | E15: Card / Stripe-style fees
A16: Customer support ($ per customer / month) | B16: 8 | E16: Applied to average customers in the month
A17: Fixed marketing spend ($ / month) | B17: 15000 | E17: Brand, content, events - not tied to new logos
A18: R&D payroll - Month 1 ($ / month) | B18: 60000 | E18: Engineering & product team
A19: R&D monthly growth (%) | B19: 0.015 | E19: Hiring pace
A20: G&A - Month 1 ($ / month) | B20: 25000 | E20: Finance, legal, office, admin
A21: G&A monthly growth (%) | B21: 0.01
A22: Capex ($ / month) | B22: 5000 | E22: Laptops, equipment
A23: Useful life of capex (months) | B23: 36 | E23: Straight-line depreciation
A24: Tax rate (%) | B24: 0.21 | E24: Applied only to positive EBIT
A26: Cash & financing | B26: Value | E26: Notes
A27: Starting cash ($) | B27: 2000000 | E27: Cash in the bank at Month 0
A28: Accounts receivable (days of revenue) | B28: 30 | E28: How long customers take to pay
A29: Equity raise amount ($) | B29: 3000000 | E29: e.g. a Series A
A30: Equity raise month | B30: 13 | E30: Month number in which the cash arrives

Sheet Revenue Build
A1: Revenue Build - customers and MRR by plan
A2: Month | B2: 0 | C2: =B2+1 -> 1 | D2: =C2+1 -> 2 | E2: =D2+1 -> 3 | F2: =E2+1 -> 4 | G2: =F2+1 -> 5 | H2: =G2+1 -> 6 | I2: =H2+1 -> 7 | J2: =I2+1 -> 8 | ... AL2: =AK2+1 -> 36
A3: Year | C3: =ROUNDUP(C2/12,0) -> 1 | D3: =ROUNDUP(D2/12,0) -> 1 | E3: =ROUNDUP(E2/12,0) -> 1 | F3: =ROUNDUP(F2/12,0) -> 1 | G3: =ROUNDUP(G2/12,0) -> 1 | H3: =ROUNDUP(H2/12,0) -> 1 | I3: =ROUNDUP(I2/12,0) -> 1 | J3: =ROUNDUP(J2/12,0) -> 1 | ... AL3: =ROUNDUP(AL2/12,0) -> 3
A5: Basic plan
A6: Beginning customers | C6: =B9 -> 100 | D6: =C9 -> 137 | E6: =D9 -> 174.89 | F6: =E9 -> 213.7433 | G6: =F9 -> 253.636 | H6: =G9 -> 294.64717 | I6: =H9 -> 336.85902 | J6: =I9 -> 380.35707 | ... AL6: =AK9 -> 2620.2643
A7: (+) New customers | C7: =Assumptions!$B$6*(1+Assumptions!$B$7)^(C$2-1) -> 40 | D7: =Assumptions!$B$6*(1+Assumptions!$B$7)^(D$2-1) -> 42 | E7: =Assumptions!$B$6*(1+Assumptions!$B$7)^(E$2-1) -> 44.1 | F7: =Assumptions!$B$6*(1+Assumptions!$B$7)^(F$2-1) -> 46.305 | G7: =Assumptions!$B$6*(1+Assumptions!$B$7)^(G$2-1) -> 48.62025 | H7: =Assumptions!$B$6*(1+Assumptions!$B$7)^(H$2-1) -> 51.051262 | I7: =Assumptions!$B$6*(1+Assumptions!$B$7)^(I$2-1) -> 53.603826 | J7: =Assumptions!$B$6*(1+Assumptions!$B$7)^(J$2-1) -> 56.284017 | ... AL7: =Assumptions!$B$6*(1+Assumptions!$B$7)^(AL$2-1) -> 220.64061
A8: (-) Churned customers | C8: =-C6*Assumptions!$B$8 -> -3 | D8: =-D6*Assumptions!$B$8 -> -4.11 | E8: =-E6*Assumptions!$B$8 -> -5.2467 | F8: =-F6*Assumptions!$B$8 -> -6.412299 | G8: =-G6*Assumptions!$B$8 -> -7.60908 | H8: =-H6*Assumptions!$B$8 -> -8.8394151 | I8: =-I6*Assumptions!$B$8 -> -10.105771 | J8: =-J6*Assumptions!$B$8 -> -11.410712 | ... AL8: =-AL6*Assumptions!$B$8 -> -78.60793
A9: Ending customers | B9: =Assumptions!B9 -> 100 | C9: =SUM(C6:C8) -> 137 | D9: =SUM(D6:D8) -> 174.89 | E9: =SUM(E6:E8) -> 213.7433 | F9: =SUM(F6:F8) -> 253.636 | G9: =SUM(G6:G8) -> 294.64717 | H9: =SUM(H6:H8) -> 336.85902 | I9: =SUM(I6:I8) -> 380.35707 | J9: =SUM(J6:J8) -> 425.23038 | ... AL9: =SUM(AL6:AL8) -> 2762.297
A10: Beginning MRR | C10: =B14 -> 4900 | D10: =C14 -> 6713 | E10: =D14 -> 8569.61 | F10: =E14 -> 10473.422 | G10: =F14 -> 12428.164 | H10: =G14 -> 14437.711 | I10: =H14 -> 16506.092 | J10: =I14 -> 18637.497 | ... AL10: =AK14 -> 128392.95
A11: (+) New MRR | C11: =C7*Assumptions!$B$5 -> 1960 | D11: =D7*Assumptions!$B$5 -> 2058 | E11: =E7*Assumptions!$B$5 -> 2160.9 | F11: =F7*Assumptions!$B$5 -> 2268.945 | G11: =G7*Assumptions!$B$5 -> 2382.3922 | H11: =H7*Assumptions!$B$5 -> 2501.5119 | I11: =I7*Assumptions!$B$5 -> 2626.5875 | J11: =J7*Assumptions!$B$5 -> 2757.9168 | ... AL11: =AL7*Assumptions!$B$5 -> 10811.39
A12: (+) Expansion MRR | C12: =C10*Assumptions!$B$10 -> 0 | D12: =D10*Assumptions!$B$10 -> 0 | E12: =E10*Assumptions!$B$10 -> 0 | F12: =F10*Assumptions!$B$10 -> 0 | G12: =G10*Assumptions!$B$10 -> 0 | H12: =H10*Assumptions!$B$10 -> 0 | I12: =I10*Assumptions!$B$10 -> 0 | J12: =J10*Assumptions!$B$10 -> 0 | ... AL12: =AL10*Assumptions!$B$10 -> 0
A13: (-) Churned MRR | C13: =-C10*Assumptions!$B$8 -> -147 | D13: =-D10*Assumptions!$B$8 -> -201.39 | E13: =-E10*Assumptions!$B$8 -> -257.0883 | F13: =-F10*Assumptions!$B$8 -> -314.20265 | G13: =-G10*Assumptions!$B$8 -> -372.84492 | H13: =-H10*Assumptions!$B$8 -> -433.13134 | I13: =-I10*Assumptions!$B$8 -> -495.18276 | J13: =-J10*Assumptions!$B$8 -> -559.1249 | ... AL13: =-AL10*Assumptions!$B$8 -> -3851.7885
A14: Ending MRR | B14: =B9*Assumptions!B5 -> 4900 | C14: =SUM(C10:C13) -> 6713 | D14: =SUM(D10:D13) -> 8569.61 | E14: =SUM(E10:E13) -> 10473.422 | F14: =SUM(F10:F13) -> 12428.164 | G14: =SUM(G10:G13) -> 14437.711 | H14: =SUM(H10:H13) -> 16506.092 | I14: =SUM(I10:I13) -> 18637.497 | J14: =SUM(J10:J13) -> 20836.289 | ... AL14: =SUM(AL10:AL13) -> 135352.55
A16: Pro plan
A17: Beginning customers | C17: =B20 -> 30 | D17: =C20 -> 44.4 | E17: =D20 -> 59.262 | F17: =E20 -> 74.61426 | G17: =F20 -> 90.48635 | H17: =G20 -> 106.90922 | I17: =H20 -> 123.91526 | J17: =I20 -> 141.53839 | ... AL17: =AK20 -> 1091.1367
A18: (+) New customers | C18: =Assumptions!$C$6*(1+Assumptions!$C$7)^(C$2-1) -> 15 | D18: =Assumptions!$C$6*(1+Assumptions!$C$7)^(D$2-1) -> 15.75 | E18: =Assumptions!$C$6*(1+Assumptions!$C$7)^(E$2-1) -> 16.5375 | F18: =Assumptions!$C$6*(1+Assumptions!$C$7)^(F$2-1) -> 17.364375 | G18: =Assumptions!$C$6*(1+Assumptions!$C$7)^(G$2-1) -> 18.232594 | H18: =Assumptions!$C$6*(1+Assumptions!$C$7)^(H$2-1) -> 19.144223 | I18: =Assumptions!$C$6*(1+Assumptions!$C$7)^(I$2-1) -> 20.101435 | J18: =Assumptions!$C$6*(1+Assumptions!$C$7)^(J$2-1) -> 21.106506 | ... AL18: =Assumptions!$C$6*(1+Assumptions!$C$7)^(AL$2-1) -> 82.740231
A19: (-) Churned customers | C19: =-C17*Assumptions!$C$8 -> -0.6 | D19: =-D17*Assumptions!$C$8 -> -0.888 | E19: =-E17*Assumptions!$C$8 -> -1.18524 | F19: =-F17*Assumptions!$C$8 -> -1.4922852 | G19: =-G17*Assumptions!$C$8 -> -1.809727 | H19: =-H17*Assumptions!$C$8 -> -2.1381843 | I19: =-I17*Assumptions!$C$8 -> -2.4783051 | J19: =-J17*Assumptions!$C$8 -> -2.8307677 | ... AL19: =-AL17*Assumptions!$C$8 -> -21.822734
A20: Ending customers | B20: =Assumptions!C9 -> 30 | C20: =SUM(C17:C19) -> 44.4 | D20: =SUM(D17:D19) -> 59.262 | E20: =SUM(E17:E19) -> 74.61426 | F20: =SUM(F17:F19) -> 90.48635 | G20: =SUM(G17:G19) -> 106.90922 | H20: =SUM(H17:H19) -> 123.91526 | I20: =SUM(I17:I19) -> 141.53839 | J20: =SUM(J17:J19) -> 159.81412 | ... AL20: =SUM(AL17:AL19) -> 1152.0542
A21: Beginning MRR | C21: =B25 -> 5970 | D21: =C25 -> 8895.3 | E21: =D25 -> 11940.597 | F21: =E25 -> 15112.154 | G21: =F25 -> 18416.543 | H21: =G25 -> 21860.663 | I21: =H25 -> 25451.757 | J21: =I25 -> 29197.425 | ... AL21: =AK25 -> 243624.82
A22: (+) New MRR | C22: =C18*Assumptions!$C$5 -> 2985 | D22: =D18*Assumptions!$C$5 -> 3134.25 | E22: =E18*Assumptions!$C$5 -> 3290.9625 | F22: =F18*Assumptions!$C$5 -> 3455.5106 | G22: =G18*Assumptions!$C$5 -> 3628.2862 | H22: =H18*Assumptions!$C$5 -> 3809.7005 | I22: =I18*Assumptions!$C$5 -> 4000.1855 | J22: =J18*Assumptions!$C$5 -> 4200.1948 | ... AL22: =AL18*Assumptions!$C$5 -> 16465.306
A23: (+) Expansion MRR | C23: =C21*Assumptions!$C$10 -> 59.7 | D23: =D21*Assumptions!$C$10 -> 88.953 | E23: =E21*Assumptions!$C$10 -> 119.40597 | F23: =F21*Assumptions!$C$10 -> 151.12154 | G23: =G21*Assumptions!$C$10 -> 184.16543 | H23: =H21*Assumptions!$C$10 -> 218.60663 | I23: =I21*Assumptions!$C$10 -> 254.51757 | J23: =J21*Assumptions!$C$10 -> 291.97425 | ... AL23: =AL21*Assumptions!$C$10 -> 2436.2482
A24: (-) Churned MRR | C24: =-C21*Assumptions!$C$8 -> -119.4 | D24: =-D21*Assumptions!$C$8 -> -177.906 | E24: =-E21*Assumptions!$C$8 -> -238.81194 | F24: =-F21*Assumptions!$C$8 -> -302.24307 | G24: =-G21*Assumptions!$C$8 -> -368.33085 | H24: =-H21*Assumptions!$C$8 -> -437.21327 | I24: =-I21*Assumptions!$C$8 -> -509.03514 | J24: =-J21*Assumptions!$C$8 -> -583.9485 | ... AL24: =-AL21*Assumptions!$C$8 -> -4872.4965
A25: Ending MRR | B25: =B20*Assumptions!C5 -> 5970 | C25: =SUM(C21:C24) -> 8895.3 | D25: =SUM(D21:D24) -> 11940.597 | E25: =SUM(E21:E24) -> 15112.154 | F25: =SUM(F21:F24) -> 18416.543 | G25: =SUM(G21:G24) -> 21860.663 | H25: =SUM(H21:H24) -> 25451.757 | I25: =SUM(I21:I24) -> 29197.425 | J25: =SUM(J21:J24) -> 33105.646 | ... AL25: =SUM(AL21:AL24) -> 257653.88
A27: Enterprise plan
A28: Beginning customers | C28: =B31 -> 3 | D28: =C31 -> 4.97 | E28: =D31 -> 7.0003 | F28: =E31 -> 9.093497 | G28: =F31 -> 11.25229 | H28: =G31 -> 13.479484 | I28: =H31 -> 15.777995 | J28: =I31 -> 18.150853 | ... AL28: =AK31 -> 131.816
A29: (+) New customers | C29: =Assumptions!$D$6*(1+Assumptions!$D$7)^(C$2-1) -> 2 | D29: =Assumptions!$D$6*(1+Assumptions!$D$7)^(D$2-1) -> 2.08 | E29: =Assumptions!$D$6*(1+Assumptions!$D$7)^(E$2-1) -> 2.1632 | F29: =Assumptions!$D$6*(1+Assumptions!$D$7)^(F$2-1) -> 2.249728 | G29: =Assumptions!$D$6*(1+Assumptions!$D$7)^(G$2-1) -> 2.3397171 | H29: =Assumptions!$D$6*(1+Assumptions!$D$7)^(H$2-1) -> 2.4333058 | I29: =Assumptions!$D$6*(1+Assumptions!$D$7)^(I$2-1) -> 2.530638 | J29: =Assumptions!$D$6*(1+Assumptions!$D$7)^(J$2-1) -> 2.6318636 | ... AL29: =Assumptions!$D$6*(1+Assumptions!$D$7)^(AL$2-1) -> 7.892178
A30: (-) Churned customers | C30: =-C28*Assumptions!$D$8 -> -0.03 | D30: =-D28*Assumptions!$D$8 -> -0.0497 | E30: =-E28*Assumptions!$D$8 -> -0.070003 | F30: =-F28*Assumptions!$D$8 -> -0.09093497 | G30: =-G28*Assumptions!$D$8 -> -0.1125229 | H30: =-H28*Assumptions!$D$8 -> -0.13479484 | I30: =-I28*Assumptions!$D$8 -> -0.15777995 | J30: =-J28*Assumptions!$D$8 -> -0.18150853 | ... AL30: =-AL28*Assumptions!$D$8 -> -1.31816
A31: Ending customers | B31: =Assumptions!D9 -> 3 | C31: =SUM(C28:C30) -> 4.97 | D31: =SUM(D28:D30) -> 7.0003 | E31: =SUM(E28:E30) -> 9.093497 | F31: =SUM(F28:F30) -> 11.25229 | G31: =SUM(G28:G30) -> 13.479484 | H31: =SUM(H28:H30) -> 15.777995 | I31: =SUM(I28:I30) -> 18.150853 | J31: =SUM(J28:J30) -> 20.601208 | ... AL31: =SUM(AL28:AL30) -> 138.39001
A32: Beginning MRR | C32: =B36 -> 2997 | D32: =C36 -> 5009.985 | E32: =D36 -> 7112.9549 | F32: =E36 -> 9309.5565 | G32: =F36 -> 11603.583 | H32: =G36 -> 13998.978 | I32: =H36 -> 16499.845 | J32: =I36 -> 19110.452 | ... AL32: =AK36 -> 160860.42
A33: (+) New MRR | C33: =C29*Assumptions!$D$5 -> 1998 | D33: =D29*Assumptions!$D$5 -> 2077.92 | E33: =E29*Assumptions!$D$5 -> 2161.0368 | F33: =F29*Assumptions!$D$5 -> 2247.4783 | G33: =G29*Assumptions!$D$5 -> 2337.3774 | H33: =H29*Assumptions!$D$5 -> 2430.8725 | I33: =I29*Assumptions!$D$5 -> 2528.1074 | J33: =J29*Assumptions!$D$5 -> 2629.2317 | ... AL33: =AL29*Assumptions!$D$5 -> 7884.2858
A34: (+) Expansion MRR | C34: =C32*Assumptions!$D$10 -> 44.955 | D34: =D32*Assumptions!$D$10 -> 75.149775 | E34: =E32*Assumptions!$D$10 -> 106.69432 | F34: =F32*Assumptions!$D$10 -> 139.64335 | G34: =G32*Assumptions!$D$10 -> 174.05374 | H34: =H32*Assumptions!$D$10 -> 209.98467 | I34: =I32*Assumptions!$D$10 -> 247.49768 | J34: =J32*Assumptions!$D$10 -> 286.65678 | ... AL34: =AL32*Assumptions!$D$10 -> 2412.9063
A35: (-) Churned MRR | C35: =-C32*Assumptions!$D$8 -> -29.97 | D35: =-D32*Assumptions!$D$8 -> -50.09985 | E35: =-E32*Assumptions!$D$8 -> -71.129549 | F35: =-F32*Assumptions!$D$8 -> -93.095565 | G35: =-G32*Assumptions!$D$8 -> -116.03583 | H35: =-H32*Assumptions!$D$8 -> -139.98978 | I35: =-I32*Assumptions!$D$8 -> -164.99845 | J35: =-J32*Assumptions!$D$8 -> -191.10452 | ... AL35: =-AL32*Assumptions!$D$8 -> -1608.6042
A36: Ending MRR | B36: =B31*Assumptions!D5 -> 2997 | C36: =SUM(C32:C35) -> 5009.985 | D36: =SUM(D32:D35) -> 7112.9549 | E36: =SUM(E32:E35) -> 9309.5565 | F36: =SUM(F32:F35) -> 11603.583 | G36: =SUM(G32:G35) -> 13998.978 | H36: =SUM(H32:H35) -> 16499.845 | I36: =SUM(I32:I35) -> 19110.452 | J36: =SUM(J32:J35) -> 21835.236 | ... AL36: =SUM(AL32:AL35) -> 169549.01
A38: Total - all plans
A39: Beginning customers | C39: =C6+C17+C28 -> 133 | D39: =D6+D17+D28 -> 186.37 | E39: =E6+E17+E28 -> 241.1523 | F39: =F6+F17+F28 -> 297.45106 | G39: =G6+G17+G28 -> 355.37464 | H39: =H6+H17+H28 -> 415.03587 | I39: =I6+I17+I28 -> 476.55227 | J39: =J6+J17+J28 -> 540.04631 | ... AL39: =AL6+AL17+AL28 -> 3843.217
A40: (+) New customers | C40: =C7+C18+C29 -> 57 | D40: =D7+D18+D29 -> 59.83 | E40: =E7+E18+E29 -> 62.8007 | F40: =F7+F18+F29 -> 65.919103 | G40: =G7+G18+G29 -> 69.192561 | H40: =H7+H18+H29 -> 72.628792 | I40: =I7+I18+I29 -> 76.235898 | J40: =J7+J18+J29 -> 80.022387 | ... AL40: =AL7+AL18+AL29 -> 311.27302
A41: (-) Churned customers | C41: =C8+C19+C30 -> -3.63 | D41: =D8+D19+D30 -> -5.0477 | E41: =E8+E19+E30 -> -6.501943 | F41: =F8+F19+F30 -> -7.9955192 | G41: =G8+G19+G30 -> -9.5313299 | H41: =H8+H19+H30 -> -11.112394 | I41: =I8+I19+I30 -> -12.741856 | J41: =J8+J19+J30 -> -14.422988 | ... AL41: =AL8+AL19+AL30 -> -101.74882
A42: Ending customers | B42: =B9+B20+B31 -> 133 | C42: =C9+C20+C31 -> 186.37 | D42: =D9+D20+D31 -> 241.1523 | E42: =E9+E20+E31 -> 297.45106 | F42: =F9+F20+F31 -> 355.37464 | G42: =G9+G20+G31 -> 415.03587 | H42: =H9+H20+H31 -> 476.55227 | I42: =I9+I20+I31 -> 540.04631 | ... AL42: =AL9+AL20+AL31 -> 4052.7412
A43: Beginning MRR | C43: =C10+C21+C32 -> 13867 | D43: =D10+D21+D32 -> 20618.285 | E43: =E10+E21+E32 -> 27623.162 | F43: =F10+F21+F32 -> 34895.132 | G43: =G10+G21+G32 -> 42448.289 | H43: =H10+H21+H32 -> 50297.353 | I43: =I10+I21+I32 -> 58457.694 | J43: =J10+J21+J32 -> 66945.374 | ... AL43: =AL10+AL21+AL32 -> 532878.2
A44: (+) New MRR | C44: =C11+C22+C33 -> 6943 | D44: =D11+D22+D33 -> 7270.17 | E44: =E11+E22+E33 -> 7612.8993 | F44: =F11+F22+F33 -> 7971.9339 | G44: =G11+G22+G33 -> 8348.0558 | H44: =H11+H22+H33 -> 8742.0848 | I44: =I11+I22+I33 -> 9154.8803 | J44: =J11+J22+J33 -> 9587.3433 | ... AL44: =AL11+AL22+AL33 -> 35160.982
...

Sheet Income Statement
A1: Income Statement ($)
A2: Month | B2: 0 | C2: =B2+1 -> 1 | D2: =C2+1 -> 2 | E2: =D2+1 -> 3 | F2: =E2+1 -> 4 | G2: =F2+1 -> 5 | H2: =G2+1 -> 6 | I2: =H2+1 -> 7 | J2: =I2+1 -> 8 | ... AL2: =AK2+1 -> 36
A3: Year | C3: =ROUNDUP(C2/12,0) -> 1 | D3: =ROUNDUP(D2/12,0) -> 1 | E3: =ROUNDUP(E2/12,0) -> 1 | F3: =ROUNDUP(F2/12,0) -> 1 | G3: =ROUNDUP(G2/12,0) -> 1 | H3: =ROUNDUP(H2/12,0) -> 1 | I3: =ROUNDUP(I2/12,0) -> 1 | J3: =ROUNDUP(J2/12,0) -> 1 | ... AL3: =ROUNDUP(AL2/12,0) -> 3
A5: Revenue | C5: ='Revenue Build'!C53 -> 17242.643 | D5: ='Revenue Build'!D53 -> 24120.723 | E5: ='Revenue Build'!E53 -> 31259.147 | F5: ='Revenue Build'!F53 -> 38671.71 | G5: ='Revenue Build'!G53 -> 46372.821 | H5: ='Revenue Build'!H53 -> 54377.523 | I5: ='Revenue Build'!I53 -> 62701.534 | J5: ='Revenue Build'!J53 -> 71361.272 | ... AL5: ='Revenue Build'!AL53 -> 547716.82
A6: Cost of revenue
A7: Hosting & infrastructure | C7: =-C5*Assumptions!$B$14 -> -2069.1171 | D7: =-D5*Assumptions!$B$14 -> -2894.4868 | E7: =-E5*Assumptions!$B$14 -> -3751.0976 | F7: =-F5*Assumptions!$B$14 -> -4640.6053 | G7: =-G5*Assumptions!$B$14 -> -5564.7385 | H7: =-H5*Assumptions!$B$14 -> -6525.3028 | I7: =-I5*Assumptions!$B$14 -> -7524.1841 | J7: =-J5*Assumptions!$B$14 -> -8563.3526 | ... AL7: =-AL5*Assumptions!$B$14 -> -65726.019
A8: Payment processing | C8: =-C5*Assumptions!$B$15 -> -517.27927 | D8: =-D5*Assumptions!$B$15 -> -723.6217 | E8: =-E5*Assumptions!$B$15 -> -937.7744 | F8: =-F5*Assumptions!$B$15 -> -1160.1513 | G8: =-G5*Assumptions!$B$15 -> -1391.1846 | H8: =-H5*Assumptions!$B$15 -> -1631.3257 | I8: =-I5*Assumptions!$B$15 -> -1881.046 | J8: =-J5*Assumptions!$B$15 -> -2140.8382 | ... AL8: =-AL5*Assumptions!$B$15 -> -16431.505
A9: Customer support | C9: =-AVERAGE('Revenue Build'!C39,'Revenue Build'!C42)*Assumptions!$B$16 -> -1277.48 | D9: =-AVERAGE('Revenue Build'!D39,'Revenue Build'!D42)*Assumptions!$B$16 -> -1710.0892 | E9: =-AVERAGE('Revenue Build'!E39,'Revenue Build'!E42)*Assumptions!$B$16 -> -2154.4134 | F9: =-AVERAGE('Revenue Build'!F39,'Revenue Build'!F42)*Assumptions!$B$16 -> -2611.3028 | G9: =-AVERAGE('Revenue Build'!G39,'Revenue Build'!G42)*Assumptions!$B$16 -> -3081.6421 | H9: =-AVERAGE('Revenue Build'!H39,'Revenue Build'!H42)*Assumptions!$B$16 -> -3566.3526 | I9: =-AVERAGE('Revenue Build'!I39,'Revenue Build'!I42)*Assumptions!$B$16 -> -4066.3943 | J9: =-AVERAGE('Revenue Build'!J39,'Revenue Build'!J42)*Assumptions!$B$16 -> -4582.7681 | ... AL9: =-AVERAGE('Revenue Build'!AL39,'Revenue Build'!AL42)*Assumptions!$B$16 -> -31583.833
A10: Total cost of revenue | C10: =SUM(C7:C9) -> -3863.8764 | D10: =SUM(D7:D9) -> -5328.1977 | E10: =SUM(E7:E9) -> -6843.2855 | F10: =SUM(F7:F9) -> -8412.0594 | G10: =SUM(G7:G9) -> -10037.565 | H10: =SUM(H7:H9) -> -11722.981 | I10: =SUM(I7:I9) -> -13471.624 | J10: =SUM(J7:J9) -> -15286.959 | ... AL10: =SUM(AL7:AL9) -> -113741.36
A11: Gross profit | C11: =C5+C10 -> 13378.766 | D11: =D5+D10 -> 18792.526 | E11: =E5+E10 -> 24415.861 | F11: =F5+F10 -> 30259.651 | G11: =G5+G10 -> 36335.256 | H11: =H5+H10 -> 42654.542 | I11: =I5+I10 -> 49229.91 | J11: =J5+J10 -> 56074.313 | ... AL11: =AL5+AL10 -> 433975.47
A12: Gross margin (%) | C12: =IF(C5<>0,C11/C5,0) -> 0.77591159 | D12: =IF(D5<>0,D11/D5,0) -> 0.77910291 | E12: =IF(E5<>0,E11/E5,0) -> 0.78107894 | F12: =IF(F5<>0,F11/F5,0) -> 0.78247512 | G12: =IF(G5<>0,G11/G5,0) -> 0.78354638 | H12: =IF(H5<>0,H11/H5,0) -> 0.78441495 | I12: =IF(I5<>0,I11/I5,0) -> 0.78514681 | J12: =IF(J5<>0,J11/J5,0) -> 0.78578074 | ... AL12: =IF(AL5<>0,AL11/AL5,0) -> 0.79233547
A13: Operating expenses
A14: Sales & marketing (CAC x new logos + fixed) | C14: =-('Revenue Build'!C7*Assumptions!$B$11+'Revenue Build'!C18*Assumptions!$C$11+'Revenue Build'!C29*Assumptions!$D$11+Assumptions!$B$17) -> -73500 | D14: =-('Revenue Build'!D7*Assumptions!$B$11+'Revenue Build'!D18*Assumptions!$C$11+'Revenue Build'!D29*Assumptions!$D$11+Assumptions!$B$17) -> -76185 | E14: =-('Revenue Build'!E7*Assumptions!$B$11+'Revenue Build'!E18*Assumptions!$C$11+'Revenue Build'!E29*Assumptions!$D$11+Assumptions!$B$17) -> -78994.65 | F14: =-('Revenue Build'!F7*Assumptions!$B$11+'Revenue Build'!F18*Assumptions!$C$11+'Revenue Build'!F29*Assumptions!$D$11+Assumptions!$B$17) -> -81934.799 | G14: =-('Revenue Build'!G7*Assumptions!$B$11+'Revenue Build'!G18*Assumptions!$C$11+'Revenue Build'!G29*Assumptions!$D$11+Assumptions!$B$17) -> -85011.571 | H14: =-('Revenue Build'!H7*Assumptions!$B$11+'Revenue Build'!H18*Assumptions!$C$11+'Revenue Build'!H29*Assumptions!$D$11+Assumptions!$B$17) -> -88231.384 | I14: =-('Revenue Build'!I7*Assumptions!$B$11+'Revenue Build'!I18*Assumptions!$C$11+'Revenue Build'!I29*Assumptions!$D$11+Assumptions!$B$17) -> -91600.956 | J14: =-('Revenue Build'!J7*Assumptions!$B$11+'Revenue Build'!J18*Assumptions!$C$11+'Revenue Build'!J29*Assumptions!$D$11+Assumptions!$B$17) -> -95127.327 | ... AL14: =-('Revenue Build'!AL7*Assumptions!$B$11+'Revenue Build'!AL18*Assumptions!$C$11+'Revenue Build'!AL29*Assumptions!$D$11+Assumptions!$B$17) -> -300008.67
A15: Research & development | C15: =-Assumptions!$B$18*(1+Assumptions!$B$19)^(C$2-1) -> -60000 | D15: =-Assumptions!$B$18*(1+Assumptions!$B$19)^(D$2-1) -> -60900 | E15: =-Assumptions!$B$18*(1+Assumptions!$B$19)^(E$2-1) -> -61813.5 | F15: =-Assumptions!$B$18*(1+Assumptions!$B$19)^(F$2-1) -> -62740.702 | G15: =-Assumptions!$B$18*(1+Assumptions!$B$19)^(G$2-1) -> -63681.813 | H15: =-Assumptions!$B$18*(1+Assumptions!$B$19)^(H$2-1) -> -64637.04 | I15: =-Assumptions!$B$18*(1+Assumptions!$B$19)^(I$2-1) -> -65606.596 | J15: =-Assumptions!$B$18*(1+Assumptions!$B$19)^(J$2-1) -> -66590.695 | ... AL15: =-Assumptions!$B$18*(1+Assumptions!$B$19)^(AL$2-1) -> -101032.88
A16: General & administrative | C16: =-Assumptions!$B$20*(1+Assumptions!$B$21)^(C$2-1) -> -25000 | D16: =-Assumptions!$B$20*(1+Assumptions!$B$21)^(D$2-1) -> -25250 | E16: =-Assumptions!$B$20*(1+Assumptions!$B$21)^(E$2-1) -> -25502.5 | F16: =-Assumptions!$B$20*(1+Assumptions!$B$21)^(F$2-1) -> -25757.525 | G16: =-Assumptions!$B$20*(1+Assumptions!$B$21)^(G$2-1) -> -26015.1 | H16: =-Assumptions!$B$20*(1+Assumptions!$B$21)^(H$2-1) -> -26275.251 | I16: =-Assumptions!$B$20*(1+Assumptions!$B$21)^(I$2-1) -> -26538.004 | J16: =-Assumptions!$B$20*(1+Assumptions!$B$21)^(J$2-1) -> -26803.384 | ... AL16: =-Assumptions!$B$20*(1+Assumptions!$B$21)^(AL$2-1) -> -35415.069
A17: Total operating expenses | C17: =SUM(C14:C16) -> -158500 | D17: =SUM(D14:D16) -> -162335 | E17: =SUM(E14:E16) -> -166310.65 | F17: =SUM(F14:F16) -> -170433.03 | G17: =SUM(G14:G16) -> -174708.48 | H17: =SUM(H14:H16) -> -179143.68 | I17: =SUM(I14:I16) -> -183745.56 | J17: =SUM(J14:J16) -> -188521.41 | ... AL17: =SUM(AL14:AL16) -> -436456.61
A18: EBITDA | C18: =C11+C17 -> -145121.23 | D18: =D11+D17 -> -143542.47 | E18: =E11+E17 -> -141894.79 | F18: =F11+F17 -> -140173.37 | G18: =G11+G17 -> -138373.23 | H18: =H11+H17 -> -136489.13 | I18: =I11+I17 -> -134515.65 | J18: =J11+J17 -> -132447.09 | ... AL18: =AL11+AL17 -> -2481.1482
A19: EBITDA margin (%) | C19: =IF(C5<>0,C18/C5,0) -> -8.4164149 | D19: =IF(D5<>0,D18/D5,0) -> -5.951002 | E19: =IF(E5<>0,E18/E5,0) -> -4.5393046 | F19: =IF(F5<>0,F18/F5,0) -> -3.6247007 | G19: =IF(G5<>0,G18/G5,0) -> -2.9839295 | H19: =IF(H5<>0,H18/H5,0) -> -2.5100285 | I19: =IF(I5<>0,I18/I5,0) -> -2.1453326 | J19: =IF(J5<>0,J18/J5,0) -> -1.856008 | ... AL19: =IF(AL5<>0,AL18/AL5,0) -> -0.0045299836
A20: Depreciation & amortization | C20: =SUM('Cash Flow'!$C$11:C11)/Assumptions!$B$23 -> -138.88889 | D20: =SUM('Cash Flow'!$C$11:D11)/Assumptions!$B$23 -> -277.77778 | E20: =SUM('Cash Flow'!$C$11:E11)/Assumptions!$B$23 -> -416.66667 | F20: =SUM('Cash Flow'!$C$11:F11)/Assumptions!$B$23 -> -555.55556 | G20: =SUM('Cash Flow'!$C$11:G11)/Assumptions!$B$23 -> -694.44444 | H20: =SUM('Cash Flow'!$C$11:H11)/Assumptions!$B$23 -> -833.33333 | I20: =SUM('Cash Flow'!$C$11:I11)/Assumptions!$B$23 -> -972.22222 | J20: =SUM('Cash Flow'!$C$11:J11)/Assumptions!$B$23 -> -1111.1111 | ... AL20: =SUM('Cash Flow'!$C$11:AL11)/Assumptions!$B$23 -> -5000
A21: EBIT (operating income) | C21: =C18+C20 -> -145260.12 | D21: =D18+D20 -> -143820.25 | E21: =E18+E20 -> -142311.46 | F21: =F18+F20 -> -140728.93 | G21: =G18+G20 -> -139067.67 | H21: =H18+H20 -> -137322.47 | I21: =I18+I20 -> -135487.87 | J21: =J18+J20 -> -133558.2 | ... AL21: =AL18+AL20 -> -7481.1482
A22: Income taxes | C22: =-MAX(0,C21)*Assumptions!$B$24 -> 0 | D22: =-MAX(0,D21)*Assumptions!$B$24 -> 0 | E22: =-MAX(0,E21)*Assumptions!$B$24 -> 0 | F22: =-MAX(0,F21)*Assumptions!$B$24 -> 0 | G22: =-MAX(0,G21)*Assumptions!$B$24 -> 0 | H22: =-MAX(0,H21)*Assumptions!$B$24 -> 0 | I22: =-MAX(0,I21)*Assumptions!$B$24 -> 0 | J22: =-MAX(0,J21)*Assumptions!$B$24 -> 0 | ... AL22: =-MAX(0,AL21)*Assumptions!$B$24 -> 0
A23: Net income | C23: =C21+C22 -> -145260.12 | D23: =D21+D22 -> -143820.25 | E23: =E21+E22 -> -142311.46 | F23: =F21+F22 -> -140728.93 | G23: =G21+G22 -> -139067.67 | H23: =H21+H22 -> -137322.47 | I23: =I21+I22 -> -135487.87 | J23: =J21+J22 -> -133558.2 | ... AL23: =AL21+AL22 -> -7481.1482
A24: Net margin (%) | C24: =IF(C5<>0,C23/C5,0) -> -8.4244699 | D24: =IF(D5<>0,D23/D5,0) -> -5.9625182 | E24: =IF(E5<>0,E23/E5,0) -> -4.552634 | F24: =IF(F5<>0,F23/F5,0) -> -3.6390666 | G24: =IF(G5<>0,G23/G5,0) -> -2.9989048 | H24: =IF(H5<>0,H23/H5,0) -> -2.5253534 | I24: =IF(I5<>0,I23/I5,0) -> -2.1608382 | J24: =IF(J5<>0,J23/J5,0) -> -1.8715782 | ... AL24: =IF(AL5<>0,AL23/AL5,0) -> -0.013658788

Sheet Cash Flow
A1: Cash Flow Statement ($)
A2: Month | B2: 0 | C2: =B2+1 -> 1 | D2: =C2+1 -> 2 | E2: =D2+1 -> 3 | F2: =E2+1 -> 4 | G2: =F2+1 -> 5 | H2: =G2+1 -> 6 | I2: =H2+1 -> 7 | J2: =I2+1 -> 8 | ... AL2: =AK2+1 -> 36
A3: Year | C3: =ROUNDUP(C2/12,0) -> 1 | D3: =ROUNDUP(D2/12,0) -> 1 | E3: =ROUNDUP(E2/12,0) -> 1 | F3: =ROUNDUP(F2/12,0) -> 1 | G3: =ROUNDUP(G2/12,0) -> 1 | H3: =ROUNDUP(H2/12,0) -> 1 | I3: =ROUNDUP(I2/12,0) -> 1 | J3: =ROUNDUP(J2/12,0) -> 1 | ... AL3: =ROUNDUP(AL2/12,0) -> 3
A5: Operating activities
A6: Net income | C6: ='Income Statement'!C23 -> -145260.12 | D6: ='Income Statement'!D23 -> -143820.25 | E6: ='Income Statement'!E23 -> -142311.46 | F6: ='Income Statement'!F23 -> -140728.93 | G6: ='Income Statement'!G23 -> -139067.67 | H6: ='Income Statement'!H23 -> -137322.47 | I6: ='Income Statement'!I23 -> -135487.87 | J6: ='Income Statement'!J23 -> -133558.2 | ... AL6: ='Income Statement'!AL23 -> -7481.1482
A7: (+) Depreciation & amortization | C7: =-'Income Statement'!C20 -> 138.88889 | D7: =-'Income Statement'!D20 -> 277.77778 | E7: =-'Income Statement'!E20 -> 416.66667 | F7: =-'Income Statement'!F20 -> 555.55556 | G7: =-'Income Statement'!G20 -> 694.44444 | H7: =-'Income Statement'!H20 -> 833.33333 | I7: =-'Income Statement'!I20 -> 972.22222 | J7: =-'Income Statement'!J20 -> 1111.1111 | ... AL7: =-'Income Statement'!AL20 -> 5000
A8: (-) Increase in accounts receivable | C8: =B20-C20 -> -3375.6425 | D8: =C20-D20 -> -6878.081 | E8: =D20-E20 -> -7138.4234 | F8: =E20-F20 -> -7412.5636 | G8: =F20-G20 -> -7701.1104 | H8: =G20-H20 -> -8004.7026 | I8: =H20-I20 -> -8324.0105 | J8: =I20-J20 -> -8659.7378 | ... AL8: =AK20-AL20 -> -29021.877
A9: Cash flow from operations | C9: =SUM(C6:C8) -> -148496.88 | D9: =SUM(D6:D8) -> -150420.56 | E9: =SUM(E6:E8) -> -149033.21 | F9: =SUM(F6:F8) -> -147585.94 | G9: =SUM(G6:G8) -> -146074.34 | H9: =SUM(H6:H8) -> -144493.84 | I9: =SUM(I6:I8) -> -142839.66 | J9: =SUM(J6:J8) -> -141106.83 | ... AL9: =SUM(AL6:AL8) -> -31503.026
A10: Investing activities
A11: Capital expenditures | C11: =-Assumptions!$B$22 -> -5000 | D11: =-Assumptions!$B$22 -> -5000 | E11: =-Assumptions!$B$22 -> -5000 | F11: =-Assumptions!$B$22 -> -5000 | G11: =-Assumptions!$B$22 -> -5000 | H11: =-Assumptions!$B$22 -> -5000 | I11: =-Assumptions!$B$22 -> -5000 | J11: =-Assumptions!$B$22 -> -5000 | ... AL11: =-Assumptions!$B$22 -> -5000
A12: Cash flow from investing | C12: =C11 -> -5000 | D12: =D11 -> -5000 | E12: =E11 -> -5000 | F12: =F11 -> -5000 | G12: =G11 -> -5000 | H12: =H11 -> -5000 | I12: =I11 -> -5000 | J12: =J11 -> -5000 | ... AL12: =AL11 -> -5000
A13: Financing activities
A14: Equity raised | C14: =IF(C$2=Assumptions!$B$30,Assumptions!$B$29,0) -> 0 | D14: =IF(D$2=Assumptions!$B$30,Assumptions!$B$29,0) -> 0 | E14: =IF(E$2=Assumptions!$B$30,Assumptions!$B$29,0) -> 0 | F14: =IF(F$2=Assumptions!$B$30,Assumptions!$B$29,0) -> 0 | G14: =IF(G$2=Assumptions!$B$30,Assumptions!$B$29,0) -> 0 | H14: =IF(H$2=Assumptions!$B$30,Assumptions!$B$29,0) -> 0 | I14: =IF(I$2=Assumptions!$B$30,Assumptions!$B$29,0) -> 0 | J14: =IF(J$2=Assumptions!$B$30,Assumptions!$B$29,0) -> 0 | ... AL14: =IF(AL$2=Assumptions!$B$30,Assumptions!$B$29,0) -> 0
A15: Cash flow from financing | C15: =C14 -> 0 | D15: =D14 -> 0 | E15: =E14 -> 0 | F15: =F14 -> 0 | G15: =G14 -> 0 | H15: =H14 -> 0 | I15: =I14 -> 0 | J15: =J14 -> 0 | ... AL15: =AL14 -> 0
A17: Net change in cash | C17: =C9+C12+C15 -> -153496.88 | D17: =D9+D12+D15 -> -155420.56 | E17: =E9+E12+E15 -> -154033.21 | F17: =F9+F12+F15 -> -152585.94 | G17: =G9+G12+G15 -> -151074.34 | H17: =H9+H12+H15 -> -149493.84 | I17: =I9+I12+I15 -> -147839.66 | J17: =J9+J12+J15 -> -146106.83 | ... AL17: =AL9+AL12+AL15 -> -36503.026
A18: Beginning cash | C18: =B19 -> 2000000 | D18: =C19 -> 1846503.1 | E18: =D19 -> 1691082.6 | F18: =E19 -> 1537049.4 | G18: =F19 -> 1384463.4 | H18: =G19 -> 1233389.1 | I18: =H19 -> 1083895.2 | J18: =I19 -> 936055.59 | ... AL18: =AK19 -> 969318.5
A19: Ending cash | B19: =Assumptions!B27 -> 2000000 | C19: =C18+C17 -> 1846503.1 | D19: =D18+D17 -> 1691082.6 | E19: =E18+E17 -> 1537049.4 | F19: =F18+F17 -> 1384463.4 | G19: =G18+G17 -> 1233389.1 | H19: =H18+H17 -> 1083895.2 | I19: =I18+I17 -> 936055.59 | J19: =J18+J17 -> 789948.76 | ... AL19: =AL18+AL17 -> 932815.47
A20: Accounts receivable balance | B20: ='Revenue Build'!B47*Assumptions!B28/30 -> 13867 | C20: ='Income Statement'!C5*Assumptions!$B$28/30 -> 17242.643 | D20: ='Income Statement'!D5*Assumptions!$B$28/30 -> 24120.723 | E20: ='Income Statement'!E5*Assumptions!$B$28/30 -> 31259.147 | F20: ='Income Statement'!F5*Assumptions!$B$28/30 -> 38671.71 | G20: ='Income Statement'!G5*Assumptions!$B$28/30 -> 46372.821 | H20: ='Income Statement'!H5*Assumptions!$B$28/30 -> 54377.523 | I20: ='Income Statement'!I5*Assumptions!$B$28/30 -> 62701.534 | J20: ='Income Statement'!J5*Assumptions!$B$28/30 -> 71361.272 | ... AL20: ='Income Statement'!AL5*Assumptions!$B$28/30 -> 547716.82
A21: Burn & runway
A22: Free cash flow (CFO + CFI) | C22: =C9+C12 -> -153496.88 | D22: =D9+D12 -> -155420.56 | E22: =E9+E12 -> -154033.21 | F22: =F9+F12 -> -152585.94 | G22: =G9+G12 -> -151074.34 | H22: =H9+H12 -> -149493.84 | I22: =I9+I12 -> -147839.66 | J22: =J9+J12 -> -146106.83 | ... AL22: =AL9+AL12 -> -36503.026
A23: Monthly burn | C23: =MAX(0,-C22) -> 153496.88 | D23: =MAX(0,-D22) -> 155420.56 | E23: =MAX(0,-E22) -> 154033.21 | F23: =MAX(0,-F22) -> 152585.94 | G23: =MAX(0,-G22) -> 151074.34 | H23: =MAX(0,-H22) -> 149493.84 | I23: =MAX(0,-I22) -> 147839.66 | J23: =MAX(0,-J22) -> 146106.83 | ... AL23: =MAX(0,-AL22) -> 36503.026
A24: Runway at current burn (months) | C24: =IF(C23>0,C19/C23,"CF positive") -> 12.029581 | D24: =IF(D23>0,D19/D23,"CF positive") -> 10.880688 | E24: =IF(E23>0,E19/E23,"CF positive") -> 9.978688 | F24: =IF(F23>0,F19/F23,"CF positive") -> 9.0733355 | G24: =IF(G23>0,G19/G23,"CF positive") -> 8.1641203 | H24: =IF(H23>0,H19/H23,"CF positive") -> 7.2504344 | I24: =IF(I23>0,I19/I23,"CF positive") -> 6.3315595 | J24: =IF(J23>0,J19/J23,"CF positive") -> 5.4066518 | ... AL24: =IF(AL23>0,AL19/AL23,"CF positive") -> 25.55447
