Workbook

Sheet Start Here
B1: What is Docebo's stock price secretly betting on?
B2: Noah Alazar Research | Reverse DCF of Docebo Inc. (TSX: DCBO) | Built on reported numbers only
B4: THE IDEA
B5: Normal model: assumptions -> value. Reverse model: today's price -> the assumption the market must believe.
B6: The lever we solve for is NET REVENUE RETENTION (NRR): of every $100 existing customers paid last year, how much they pay this year.
B7: Docebo reports NRR of 99% (FY2025). We find the NRR that today's share price implies and compare the two.
B9: RULE FOR EVERY NUMBER
B10: Each input is labelled: REPORTED (from Docebo filings or market data), CALCULATED (formula on reported numbers), COMPANY TARGET, or CONVENTION.
B11: There are no analyst guesses. The 'Sources' tab lists every hard-coded number with the document it came from.
B13: HOW THE TABS FLOW
B14: 1. Inputs - 8 quarters of reported ARR, revenue, adjusted EBITDA and free cash flow + price, shares, cash, debt.
B15: 2. Reverse DCF - THE ANSWER: market-implied NRR vs. reported NRR (solved live, no macro).
... B37: - Adjusted EBITDA excludes stock-based pay, restructuring (severance) and acquisition costs. Free cash flow conversion uses FY2025 actual cash, which does include cash severance.

Sheet Inputs
A1: Inputs - Docebo Inc. (TSX: DCBO) reported figures
A2: US$ millions unless stated. Blue = typed from a source (hover a cell for the exact document). Black = formula.
A4: Market & balance sheet | B4: Value | C4: Unit | J4: Type | K4: Source
A5: Share price (TSX: DCBO) | B5: 33.22 | C5: C$ | J5: REPORTED | K5: TSX close 17-Sep-2026 (Investing.com / TMX Money). Update on each run.
A6: USD/CAD exchange rate (same day) | B6: 1.3991 | C6: C$ per US$ | J6: REPORTED | K6: Mid-market rate 17-Sep-2026 (MTFX). Verify on Bank of Canada daily rates.
A7: Shares held by Intercap | B7: 15.9 | C7: millions | J7: REPORTED | K7: SIB final results, 11-Sep-2026: Intercap owns 15,900,000 shares
A8: Intercap ownership | B8: 0.637 | C8: % | J8: REPORTED | K8: SIB final results, 11-Sep-2026: approx. 63.7% of shares outstanding
A9: Shares outstanding (after buyback) | B9: =B7/B8 -> 24.960754 | C9: millions | J9: CALCULATED | K9: 15.9M / 63.7%
A10: Market capitalization | B10: =B5*B9 -> 829.19623 | C10: C$ m | J10: CALCULATED | K10: Price x shares
A11: Cash & equivalents, 30-Jun-2026 | B11: 45.7 | C11: US$ m | J11: REPORTED | K11: Docebo release 17-Jul-2026 (SIB + preliminary Q2-2026 results)
A12: Cash paid in the buyback (Sep-2026) | B12: 2.4833 | C12: US$ m | J12: REPORTED | K12: SIB final results, 11-Sep-2026: 99,332 shares x US$25.00 = US$2,483,300
A13: Cash after buyback | B13: =B11-B12 -> 43.2167 | C13: US$ m | J13: CALCULATED | K13: Matches the post-buyback share count
A14: Total borrowings, 30-Jun-2026 | B14: 88 | C14: US$ m | J14: REPORTED | K14: Docebo release 17-Jul-2026
A15: Net debt | B15: =B14-B13 -> 44.7833 | C15: US$ m | J15: CALCULATED | K15: Debt - cash
A16: Gross margin (Q2-2026) | B16: 0.794 | C16: % | J16: REPORTED | K16: Docebo Q2-2026 press release, 7 Aug 2026 (sec.gov 6-K docebo2026q2pr): 79.4%
A17: Net revenue retention, FY2025 | B17: 0.99 | C17: % | J17: REPORTED | K17: Q4-2025 earnings call: net dollar retention 99% (Globe and Mail coverage)
A18: Net revenue retention ex-AWS, FY2025 | B18: 1.01 | C18: % | J18: REPORTED | K18: Q4-2025 earnings call: 101% excluding AWS
A19: Management target: adj. EBITDA margin by 2028 | B19: 0.24 | C19: % | J19: COMPANY TARGET | K19: Docebo long-term model: >$80M adj. EBITDA by 2028 = 24% margin (Investing.com)
A20: Canada 10-year bond yield | B20: 0.0399 | C20: % | J20: REPORTED | K20: 29-Sep-2026 (Trading Economics). Used only for the CAPM cross-check.
A22: Quarterly history (US$ m) | B22: Q3-24 | C22: Q4-24 | D22: Q1-25 | E22: Q2-25 | F22: Q3-25 | G22: Q4-25 | H22: Q1-26 | I22: Q2-26 | J22: Type | K22: Source
A23: ARR (annual recurring revenue) | B23: 214.1 | C23: 219.7 | D23: 225.1 | E23: 233.1 | F23: 235.6 | G23: 238.1 | H23: 248.9 | I23: 255.1 | J23: REPORTED | K23: Each quarter's own press release (hover any cell for the exact document)
A24: Total revenue | B24: 55.4 | C24: 57 | D24: 57.3 | E24: 60.7 | F24: 61.6 | G24: 63 | H24: 65.6 | I24: 68.7 | J24: REPORTED | K24: Each quarter's own press release (hover any cell for the exact document)
A25: Adjusted EBITDA | B25: 8.7 | C25: 9.5 | D25: 8.9 | E25: 9.2 | F25: 12.4 | G25: 13.3 | H25: 11 | I25: 11.2 | J25: REPORTED | K25: Each quarter's own press release (hover any cell for the exact document)
A26: Free cash flow (company definition) | B26: 4.5 | C26: 10.1 | D26: 9 | E26: 11.4 | F26: 5.7 | G26: 12.3 | H26: 27.6 | I26: 3.1 | J26: REPORTED | K26: Each quarter's own press release (hover any cell for the exact document)
A27: FCF margin (%) | B27: =B26/B24 -> 0.081227437 | C27: =C26/C24 -> 0.17719298 | D27: =D26/D24 -> 0.15706806 | E27: =E26/E24 -> 0.1878089 | F27: =F26/F24 -> 0.092532468 | G27: =G26/G24 -> 0.1952381 | H27: =H26/H24 -> 0.42073171 | I27: =I26/I24 -> 0.045123726 | J27: CALCULATED
A28: Adj. EBITDA margin (%) | B28: =B25/B24 -> 0.15703971 | C28: =C25/C24 -> 0.16666667 | D28: =D25/D24 -> 0.15532286 | E28: =E25/E24 -> 0.15156507 | F28: =F25/F24 -> 0.2012987 | G28: =G25/G24 -> 0.21111111 | H28: =H25/H24 -> 0.16768293 | I28: =I25/I24 -> 0.16302766 | J28: CALCULATED
A29: ARR growth vs. same quarter last year (%) | F29: =F23/B23-1 -> 0.10042036 | G29: =G23/C23-1 -> 0.083750569 | H29: =H23/D23-1 -> 0.10573079 | I29: =I23/E23-1 -> 0.094380094 | J29: CALCULATED
A31: Derived from the reported figures | B31: Value | C31: Unit | J31: Type | K31: How
A32: LTM revenue (Q3-25 to Q2-26) | B32: =SUM(F24:I24) -> 258.9 | J32: CALCULATED | K32: Sum of last 4 quarters
A33: LTM adjusted EBITDA | B33: =SUM(F25:I25) -> 47.9 | J33: CALCULATED
A34: LTM free cash flow | B34: =SUM(F26:I26) -> 48.7 | J34: CALCULATED
A35: LTM adj. EBITDA margin | B35: =B33/B32 -> 0.18501352 | J35: CALCULATED | K35: Starting margin in the forecast
A36: LTM FCF margin | B36: =B34/B32 -> 0.18810351 | J36: CALCULATED | K36: Flattered by customer prepayments in Q1-26 (42% FCF margin)
A37: FY2025 adjusted EBITDA (Q1-25 to Q4-25) | B37: =SUM(D25:G25) -> 43.8 | J37: CALCULATED
A38: FY2025 free cash flow | B38: =SUM(D26:G26) -> 38.4 | J38: CALCULATED | K38: Matches the US$38.4M Docebo reported for FY2025
A39: FY2025 FCF conversion (FCF / adj. EBITDA) | B39: =B38/B37 -> 0.87671233 | J39: CALCULATED | K39: A full calendar year, so prepayment timing evens out
A40: ARR now (30-Jun-2026) | B40: =I23 -> 255.1 | J40: CALCULATED | K40: Forecast starting point
A41: ARR one year ago (30-Jun-2025) | B41: =E23 -> 233.1 | J41: CALCULATED
A42: Net new ARR, last 12 months | B42: =B40-B41 -> 22 | J42: CALCULATED | K42: Ending - starting
A43: New-customer ARR, last 12 months | B43: =B42+(1-B17)*B41 -> 24.331 | J43: CALCULATED | K43: Net new ARR + ARR lost at reported NRR. Includes acquired 365Talents ARR (not broken out by Docebo)
...

Sheet Reverse DCF
A1: Reverse DCF - the retention rate today's price is betting on
A2: Solved live: the price is computed for NRR from 120% down to 50% below, then interpolated at the market price.
A4: Market price today (C$) | H4: =Inputs!B5 -> 33.22
A5: MARKET-IMPLIED NET REVENUE RETENTION | H5: =IF(H4>N30,"above 120%",IF(H4<N170,"below 50%",INDEX($A$30:$A$170,MATCH(H4,$N$30:$N$170,-1))-(INDEX($N$30:$N$170,MATCH(H4,$N$30:$N$170,-1))-H4)/(INDEX($N$30:$N$170,MATCH(H4,$N$30:$N$170,-1))-INDEX($N$30:$N$170,MATCH(H4,$N$30:$N$170,-1)+1))*0.005)) -> 0.90251822
A6: Reported net revenue retention (FY2025) | H6: =Inputs!B17 -> 0.99
A7: Gap: reported minus implied (percentage points) | H7: =IFERROR(H6-H5,"n/a") -> 0.087481777
A8: Implied net ARR lost from existing customers per year | H8: =IFERROR(1-H5,"n/a") -> 0.097481777
A9: Reported net ARR lost per year | H9: =1-H6 -> 0.01
A10: Model price at reported NRR (C$) | H10: =N173 -> 53.530345
A11: Check: model price at implied NRR (C$) - should equal market | H11: =N174 -> 33.216469
A13: =IF(ISNUMBER(H5),IF(H5<H6,"PESSIMISTIC: the price only makes sense if existing customers pay about "&TEXT(1-H5,"0%")&" less every year (NRR "&TEXT(H5,"0%")&"). Docebo reports NRR of "&TEXT(H6,"0%")&" - a loss of only "&TEXT(1-H6,"0%")&".","OPTIMISTIC: the price needs NRR of "&TEXT(H5,"0.0%")&" - better than the "&TEXT(H6,"0%")&" Docebo reports."),"Implied NRR is outside 50-120%: check the inputs.") -> PESSIMISTIC: the price only makes sense if existing customers pay about 10% less every year (NRR 90%). Docebo reports NRR of 99% - a loss of only 1%.
A15: Implied NRR BELOW reported = market pessimistic (stock may be cheap if the reported number holds). ABOVE = market optimistic.
A16: Cross-check with Goal Seek (see Start Here). Both answers should agree to about 0.1 percentage point.
A27: Engine: price for each NRR (same maths as ARR Model + DCF, one row per NRR)
A29: NRR | B29: ARR Y0 | C29: ARR Y1 | D29: ARR Y2 | E29: ARR Y3 | F29: ARR Y4 | G29: ARR Y5 | H29: ARR Y6 | I29: ARR Y7 | J29: ARR Y8 | K29: ARR Y9 | L29: ARR Y10 | M29: EV (US$m) | N29: Price C$
A30: 1.2 | B30: ='ARR Model'!$B$15 -> 255.1 | C30: =B30*$A30+'ARR Model'!C$13 -> 330.451 | D30: =C30*$A30+'ARR Model'!D$13 -> 420.8722 | E30: =D30*$A30+'ARR Model'!E$13 -> 529.37764 | F30: =E30*$A30+'ARR Model'!F$13 -> 659.58417 | G30: =F30*$A30+'ARR Model'!G$13 -> 815.832 | H30: =G30*$A30+'ARR Model'!H$13 -> 1003.3294 | I30: =H30*$A30+'ARR Model'!I$13 -> 1228.3263 | J30: =I30*$A30+'ARR Model'!J$13 -> 1498.3225 | ... L30: =K30*$A30+'ARR Model'!L$13 -> 2211.1127 | M30: =SUMPRODUCT((B30:K30+C30:L30)/2*Inputs!$B$44,'ARR Model'!$C$9:$L$9,DCF!$C$5:$L$5)+AVERAGE(K30,L30)*Inputs!$B$44*'ARR Model'!$L$9*(1+Assumptions!$C$11)/(Assumptions!$C$10-Assumptions!$C$11)*DCF!$L$5 -> 3480.7922 | N30: =(M30+Inputs!$B$13-Inputs!$B$14)/Inputs!$B$9*Inputs!$B$6 -> 192.59515
A31: 1.195 | B31: ='ARR Model'!$B$15 -> 255.1 | C31: =B31*$A31+'ARR Model'!C$13 -> 329.1755 | D31: =C31*$A31+'ARR Model'!D$13 -> 417.69572 | E31: =D31*$A31+'ARR Model'!E$13 -> 523.47739 | F31: =E31*$A31+'ARR Model'!F$13 -> 649.88648 | G31: =F31*$A31+'ARR Model'!G$13 -> 800.94534 | H31: =G31*$A31+'ARR Model'!H$13 -> 981.46068 | I31: =H31*$A31+'ARR Model'!I$13 -> 1197.1765 | J31: =I31*$A31+'ARR Model'!J$13 -> 1454.9569 | ... L31: =K31*$A31+'ARR Model'!L$13 -> 2131.1214 | M31: =SUMPRODUCT((B31:K31+C31:L31)/2*Inputs!$B$44,'ARR Model'!$C$9:$L$9,DCF!$C$5:$L$5)+AVERAGE(K31,L31)*Inputs!$B$44*'ARR Model'!$L$9*(1+Assumptions!$C$11)/(Assumptions!$C$10-Assumptions!$C$11)*DCF!$L$5 -> 3374.6283 | N31: =(M31+Inputs!$B$13-Inputs!$B$14)/Inputs!$B$9*Inputs!$B$6 -> 186.64445
A32: 1.19 | B32: ='ARR Model'!$B$15 -> 255.1 | C32: =B32*$A32+'ARR Model'!C$13 -> 327.9 | D32: =C32*$A32+'ARR Model'!D$13 -> 414.532 | E32: =D32*$A32+'ARR Model'!E$13 -> 517.62408 | F32: =E32*$A32+'ARR Model'!F$13 -> 640.30366 | G32: =F32*$A32+'ARR Model'!G$13 -> 786.29235 | H32: =G32*$A32+'ARR Model'!H$13 -> 960.0189 | I32: =H32*$A32+'ARR Model'!I$13 -> 1166.7535 | J32: =I32*$A32+'ARR Model'!J$13 -> 1412.7676 | ... L32: =K32*$A32+'ARR Model'!L$13 -> 2053.9052 | M32: =SUMPRODUCT((B32:K32+C32:L32)/2*Inputs!$B$44,'ARR Model'!$C$9:$L$9,DCF!$C$5:$L$5)+AVERAGE(K32,L32)*Inputs!$B$44*'ARR Model'!$L$9*(1+Assumptions!$C$11)/(Assumptions!$C$10-Assumptions!$C$11)*DCF!$L$5 -> 3271.7641 | N32: =(M32+Inputs!$B$13-Inputs!$B$14)/Inputs!$B$9*Inputs!$B$6 -> 180.87871
A33: 1.185 | B33: ='ARR Model'!$B$15 -> 255.1 | C33: =B33*$A33+'ARR Model'!C$13 -> 326.6245 | D33: =C33*$A33+'ARR Model'!D$13 -> 411.38103 | E33: =D33*$A33+'ARR Model'!E$13 -> 511.81752 | F33: =E33*$A33+'ARR Model'!F$13 -> 630.83477 | G33: =F33*$A33+'ARR Model'!G$13 -> 771.8702 | H33: =G33*$A33+'ARR Model'!H$13 -> 938.99718 | I33: =H33*$A33+'ARR Model'!I$13 -> 1137.0427 | J33: =I33*$A33+'ARR Model'!J$13 -> 1371.7266 | ... L33: =K33*$A33+'ARR Model'!L$13 -> 1979.376 | M33: =SUMPRODUCT((B33:K33+C33:L33)/2*Inputs!$B$44,'ARR Model'!$C$9:$L$9,DCF!$C$5:$L$5)+AVERAGE(K33,L33)*Inputs!$B$44*'ARR Model'!$L$9*(1+Assumptions!$C$11)/(Assumptions!$C$10-Assumptions!$C$11)*DCF!$L$5 -> 3172.1036 | N33: =(M33+Inputs!$B$13-Inputs!$B$14)/Inputs!$B$9*Inputs!$B$6 -> 175.29254
A34: 1.18 | B34: ='ARR Model'!$B$15 -> 255.1 | C34: =B34*$A34+'ARR Model'!C$13 -> 325.349 | D34: =C34*$A34+'ARR Model'!D$13 -> 408.24282 | E34: =D34*$A34+'ARR Model'!E$13 -> 506.05753 | F34: =E34*$A34+'ARR Model'!F$13 -> 621.47888 | G34: =F34*$A34+'ARR Model'!G$13 -> 757.67608 | H34: =G34*$A34+'ARR Model'!H$13 -> 918.38878 | I34: =H34*$A34+'ARR Model'!I$13 -> 1108.0298 | J34: =I34*$A34+'ARR Model'!J$13 -> 1331.8061 | ... L34: =K34*$A34+'ARR Model'!L$13 -> 1907.4484 | M34: =SUMPRODUCT((B34:K34+C34:L34)/2*Inputs!$B$44,'ARR Model'!$C$9:$L$9,DCF!$C$5:$L$5)+AVERAGE(K34,L34)*Inputs!$B$44*'ARR Model'!$L$9*(1+Assumptions!$C$11)/(Assumptions!$C$10-Assumptions!$C$11)*DCF!$L$5 -> 3075.5538 | N34: =(M34+Inputs!$B$13-Inputs!$B$14)/Inputs!$B$9*Inputs!$B$6 -> 169.88073
A35: 1.175 | B35: ='ARR Model'!$B$15 -> 255.1 | C35: =B35*$A35+'ARR Model'!C$13 -> 324.0735 | D35: =C35*$A35+'ARR Model'!D$13 -> 405.11736 | E35: =D35*$A35+'ARR Model'!E$13 -> 500.3439 | F35: =E35*$A35+'ARR Model'!F$13 -> 612.23508 | G35: =F35*$A35+'ARR Model'!G$13 -> 743.70722 | H35: =G35*$A35+'ARR Model'!H$13 -> 898.18699 | I35: =H35*$A35+'ARR Model'!I$13 -> 1079.7007 | J35: =I35*$A35+'ARR Model'!J$13 -> 1292.9793 | ... L35: =K35*$A35+'ARR Model'!L$13 -> 1838.0395 | M35: =SUMPRODUCT((B35:K35+C35:L35)/2*Inputs!$B$44,'ARR Model'!$C$9:$L$9,DCF!$C$5:$L$5)+AVERAGE(K35,L35)*Inputs!$B$44*'ARR Model'!$L$9*(1+Assumptions!$C$11)/(Assumptions!$C$10-Assumptions!$C$11)*DCF!$L$5 -> 2982.0236 | N35: =(M35+Inputs!$B$13-Inputs!$B$14)/Inputs!$B$9*Inputs!$B$6 -> 164.63818
A36: 1.17 | B36: ='ARR Model'!$B$15 -> 255.1 | C36: =B36*$A36+'ARR Model'!C$13 -> 322.798 | D36: =C36*$A36+'ARR Model'!D$13 -> 402.00466 | E36: =D36*$A36+'ARR Model'!E$13 -> 494.67645 | F36: =E36*$A36+'ARR Model'!F$13 -> 603.10245 | G36: =F36*$A36+'ARR Model'!G$13 -> 729.96087 | H36: =G36*$A36+'ARR Model'!H$13 -> 878.38521 | I36: =H36*$A36+'ARR Model'!I$13 -> 1052.0417 | J36: =I36*$A36+'ARR Model'!J$13 -> 1255.2198 | ... L36: =K36*$A36+'ARR Model'!L$13 -> 1771.0686 | M36: =SUMPRODUCT((B36:K36+C36:L36)/2*Inputs!$B$44,'ARR Model'!$C$9:$L$9,DCF!$C$5:$L$5)+AVERAGE(K36,L36)*Inputs!$B$44*'ARR Model'!$L$9*(1+Assumptions!$C$11)/(Assumptions!$C$10-Assumptions!$C$11)*DCF!$L$5 -> 2891.4247 | N36: =(M36+Inputs!$B$13-Inputs!$B$14)/Inputs!$B$9*Inputs!$B$6 -> 159.55993
A37: 1.165 | B37: ='ARR Model'!$B$15 -> 255.1 | C37: =B37*$A37+'ARR Model'!C$13 -> 321.5225 | D37: =C37*$A37+'ARR Model'!D$13 -> 398.90471 | E37: =D37*$A37+'ARR Model'!E$13 -> 489.05499 | F37: =E37*$A37+'ARR Model'!F$13 -> 594.08006 | G37: =F37*$A37+'ARR Model'!G$13 -> 716.43427 | H37: =G37*$A37+'ARR Model'!H$13 -> 858.97693 | I37: =H37*$A37+'ARR Model'!I$13 -> 1025.0391 | J37: =I37*$A37+'ARR Model'!J$13 -> 1218.5016 | ... L37: =K37*$A37+'ARR Model'!L$13 -> 1706.4574 | M37: =SUMPRODUCT((B37:K37+C37:L37)/2*Inputs!$B$44,'ARR Model'!$C$9:$L$9,DCF!$C$5:$L$5)+AVERAGE(K37,L37)*Inputs!$B$44*'ARR Model'!$L$9*(1+Assumptions!$C$11)/(Assumptions!$C$10-Assumptions!$C$11)*DCF!$L$5 -> 2803.6709 | N37: =(M37+Inputs!$B$13-Inputs!$B$14)/Inputs!$B$9*Inputs!$B$6 -> 154.64115
A38: 1.16 | B38: ='ARR Model'!$B$15 -> 255.1 | C38: =B38*$A38+'ARR Model'!C$13 -> 320.247 | D38: =C38*$A38+'ARR Model'!D$13 -> 395.81752 | E38: =D38*$A38+'ARR Model'!E$13 -> 483.47932 | F38: =E38*$A38+'ARR Model'!F$13 -> 585.16701 | G38: =F38*$A38+'ARR Model'!G$13 -> 703.12474 | H38: =G38*$A38+'ARR Model'!H$13 -> 839.9557 | I38: =H38*$A38+'ARR Model'!I$13 -> 998.67961 | J38: =I38*$A38+'ARR Model'!J$13 -> 1182.7993 | ... L38: =K38*$A38+'ARR Model'!L$13 -> 1644.1298 | M38: =SUMPRODUCT((B38:K38+C38:L38)/2*Inputs!$B$44,'ARR Model'!$C$9:$L$9,DCF!$C$5:$L$5)+AVERAGE(K38,L38)*Inputs!$B$44*'ARR Model'!$L$9*(1+Assumptions!$C$11)/(Assumptions!$C$10-Assumptions!$C$11)*DCF!$L$5 -> 2718.6785 | N38: =(M38+Inputs!$B$13-Inputs!$B$14)/Inputs!$B$9*Inputs!$B$6 -> 149.87716
A39: 1.155 | B39: ='ARR Model'!$B$15 -> 255.1 | C39: =B39*$A39+'ARR Model'!C$13 -> 318.9715 | D39: =C39*$A39+'ARR Model'!D$13 -> 392.74308 | E39: =D39*$A39+'ARR Model'!E$13 -> 477.94926 | F39: =E39*$A39+'ARR Model'!F$13 -> 576.3624 | G39: =F39*$A39+'ARR Model'!G$13 -> 690.02957 | H39: =G39*$A39+'ARR Model'!H$13 -> 821.31515 | I39: =H39*$A39+'ARR Model'!I$13 -> 972.95 | J39: =I39*$A39+'ARR Model'!J$13 -> 1148.0882 | ... L39: =K39*$A39+'ARR Model'!L$13 -> 1584.0117 | M39: =SUMPRODUCT((B39:K39+C39:L39)/2*Inputs!$B$44,'ARR Model'!$C$9:$L$9,DCF!$C$5:$L$5)+AVERAGE(K39,L39)*Inputs!$B$44*'ARR Model'!$L$9*(1+Assumptions!$C$11)/(Assumptions!$C$10-Assumptions!$C$11)*DCF!$L$5 -> 2636.3657 | N39: =(M39+Inputs!$B$13-Inputs!$B$14)/Inputs!$B$9*Inputs!$B$6 -> 145.26336
A40: 1.15 | B40: ='ARR Model'!$B$15 -> 255.1 | C40: =B40*$A40+'ARR Model'!C$13 -> 317.696 | D40: =C40*$A40+'ARR Model'!D$13 -> 389.6814 | E40: =D40*$A40+'ARR Model'!E$13 -> 472.46461 | F40: =E40*$A40+'ARR Model'!F$13 -> 567.6653 | G40: =F40*$A40+'ARR Model'!G$13 -> 677.1461 | H40: =G40*$A40+'ARR Model'!H$13 -> 803.04901 | I40: =H40*$A40+'ARR Model'!I$13 -> 947.83736 | J40: =I40*$A40+'ARR Model'!J$13 -> 1114.344 | ... L40: =K40*$A40+'ARR Model'!L$13 -> 1526.0315 | M40: =SUMPRODUCT((B40:K40+C40:L40)/2*Inputs!$B$44,'ARR Model'!$C$9:$L$9,DCF!$C$5:$L$5)+AVERAGE(K40,L40)*Inputs!$B$44*'ARR Model'!$L$9*(1+Assumptions!$C$11)/(Assumptions!$C$10-Assumptions!$C$11)*DCF!$L$5 -> 2556.6531 | N40: =(M40+Inputs!$B$13-Inputs!$B$14)/Inputs!$B$9*Inputs!$B$6 -> 140.79531
A41: 1.145 | B41: ='ARR Model'!$B$15 -> 255.1 | C41: =B41*$A41+'ARR Model'!C$13 -> 316.4205 | D41: =C41*$A41+'ARR Model'!D$13 -> 386.63247 | E41: =D41*$A41+'ARR Model'!E$13 -> 467.02518 | F41: =E41*$A41+'ARR Model'!F$13 -> 559.07483 | G41: =F41*$A41+'ARR Model'!G$13 -> 664.47168 | H41: =G41*$A41+'ARR Model'!H$13 -> 785.15108 | I41: =H41*$A41+'ARR Model'!I$13 -> 923.32898 | J41: =I41*$A41+'ARR Model'!J$13 -> 1081.5427 | ... L41: =K41*$A41+'ARR Model'!L$13 -> 1470.1195 | M41: =SUMPRODUCT((B41:K41+C41:L41)/2*Inputs!$B$44,'ARR Model'!$C$9:$L$9,DCF!$C$5:$L$5)+AVERAGE(K41,L41)*Inputs!$B$44*'ARR Model'!$L$9*(1+Assumptions!$C$11)/(Assumptions!$C$10-Assumptions!$C$11)*DCF!$L$5 -> 2479.4633 | N41: =(M41+Inputs!$B$13-Inputs!$B$14)/Inputs!$B$9*Inputs!$B$6 -> 136.46867
... A170: 0.5 | B170: ='ARR Model'!$B$15 -> 255.1 | C170: =B170*$A170+'ARR Model'!C$13 -> 151.881 | D170: =C170*$A170+'ARR Model'!D$13 -> 100.2715 | E170: =D170*$A170+'ARR Model'!E$13 -> 74.46675 | F170: =E170*$A170+'ARR Model'!F$13 -> 61.564375 | G170: =F170*$A170+'ARR Model'!G$13 -> 55.113188 | H170: =G170*$A170+'ARR Model'!H$13 -> 51.887594 | I170: =H170*$A170+'ARR Model'!I$13 -> 50.274797 | J170: =I170*$A170+'ARR Model'!J$13 -> 49.468398 | ... L170: =K170*$A170+'ARR Model'!L$13 -> 48.8636 | M170: =SUMPRODUCT((B170:K170+C170:L170)/2*Inputs!$B$44,'ARR Model'!$C$9:$L$9,DCF!$C$5:$L$5)+AVERAGE(K170,L170)*Inputs!$B$44*'ARR Model'!$L$9*(1+Assumptions!$C$11)/(Assumptions!$C$10-Assumptions!$C$11)*DCF!$L$5 -> 177.14289 | N170: =(M170+Inputs!$B$13-Inputs!$B$14)/Inputs!$B$9*Inputs!$B$6 -> 7.419019
A172: Checks
A173: =Inputs!B17 -> 0.99 | B173: ='ARR Model'!$B$15 -> 255.1 | C173: =B173*$A173+'ARR Model'!C$13 -> 276.88 | D173: =C173*$A173+'ARR Model'!D$13 -> 298.4422 | E173: =D173*$A173+'ARR Model'!E$13 -> 319.78878 | F173: =E173*$A173+'ARR Model'!F$13 -> 340.92189 | G173: =F173*$A173+'ARR Model'!G$13 -> 361.84367 | H173: =G173*$A173+'ARR Model'!H$13 -> 382.55623 | I173: =H173*$A173+'ARR Model'!I$13 -> 403.06167 | J173: =I173*$A173+'ARR Model'!J$13 -> 423.36206 | ... L173: =K173*$A173+'ARR Model'!L$13 -> 463.35584 | M173: =SUMPRODUCT((B173:K173+C173:L173)/2*Inputs!$B$44,'ARR Model'!$C$9:$L$9,DCF!$C$5:$L$5)+AVERAGE(K173,L173)*Inputs!$B$44*'ARR Model'!$L$9*(1+Assumptions!$C$11)/(Assumptions!$C$10-Assumptions!$C$11)*DCF!$L$5 -> 999.79562 | N173: =(M173+Inputs!$B$13-Inputs!$B$14)/Inputs!$B$9*Inputs!$B$6 -> 53.530345 | O173: <- at reported NRR
A174: =IF(ISNUMBER(H5),H5,0) -> 0.90251822 | B174: ='ARR Model'!$B$15 -> 255.1 | C174: =B174*$A174+'ARR Model'!C$13 -> 254.5634 | D174: =C174*$A174+'ARR Model'!D$13 -> 254.07911 | E174: =D174*$A174+'ARR Model'!E$13 -> 253.64202 | F174: =E174*$A174+'ARR Model'!F$13 -> 253.24755 | G174: =F174*$A174+'ARR Model'!G$13 -> 252.89153 | H174: =G174*$A174+'ARR Model'!H$13 -> 252.57021 | I174: =H174*$A174+'ARR Model'!I$13 -> 252.28022 | J174: =I174*$A174+'ARR Model'!J$13 -> 252.0185 | ... L174: =K174*$A174+'ARR Model'!L$13 -> 251.5691 | M174: =SUMPRODUCT((B174:K174+C174:L174)/2*Inputs!$B$44,'ARR Model'!$C$9:$L$9,DCF!$C$5:$L$5)+AVERAGE(K174,L174)*Inputs!$B$44*'ARR Model'!$L$9*(1+Assumptions!$C$11)/(Assumptions!$C$10-Assumptions!$C$11)*DCF!$L$5 -> 637.38432 | N174: =(M174+Inputs!$B$13-Inputs!$B$14)/Inputs!$B$9*Inputs!$B$6 -> 33.216469 | O174: <- at implied NRR
A175: =Assumptions!C5 -> 0.99 | B175: ='ARR Model'!$B$15 -> 255.1 | C175: =B175*$A175+'ARR Model'!C$13 -> 276.88 | D175: =C175*$A175+'ARR Model'!D$13 -> 298.4422 | E175: =D175*$A175+'ARR Model'!E$13 -> 319.78878 | F175: =E175*$A175+'ARR Model'!F$13 -> 340.92189 | G175: =F175*$A175+'ARR Model'!G$13 -> 361.84367 | H175: =G175*$A175+'ARR Model'!H$13 -> 382.55623 | I175: =H175*$A175+'ARR Model'!I$13 -> 403.06167 | J175: =I175*$A175+'ARR Model'!J$13 -> 423.36206 | ... L175: =K175*$A175+'ARR Model'!L$13 -> 463.35584 | M175: =SUMPRODUCT((B175:K175+C175:L175)/2*Inputs!$B$44,'ARR Model'!$C$9:$L$9,DCF!$C$5:$L$5)+AVERAGE(K175,L175)*Inputs!$B$44*'ARR Model'!$L$9*(1+Assumptions!$C$11)/(Assumptions!$C$10-Assumptions!$C$11)*DCF!$L$5 -> 999.79562 | N175: =(M175+Inputs!$B$13-Inputs!$B$14)/Inputs!$B$9*Inputs!$B$6 -> 53.530345 | O175: <- at Assumptions!C5 (must equal DCF!C18)
A176: =IF(ABS(N175-DCF!C18)<0.005,"CHECK OK: engine matches DCF tab","CHECK FAILED: engine differs from DCF tab") -> CHECK OK: engine matches DCF tab

Sheet Assumptions
B1: Assumptions - forecast levers
B2: No analyst guesses: each lever is reported, calculated from reported numbers, a company target, or a stated convention.
B4: Lever | C4: Value | D4: Type | E4: Source / reason
B5: Net revenue retention used in the DCF | C5: 0.99 | D5: REPORTED | E5: Docebo FY2025 NRR = 99%. This is the cell Goal Seek changes (the reverse-DCF lever).
B6: New-customer ARR added per year (US$ m) | C6: =Inputs!B43 -> 24.331 | D6: CALCULATED | E6: Last-12-months level from reported ARR and NRR, held flat (no growth assumed).
B7: Adj. EBITDA margin, long-term | C7: =Inputs!B19 -> 0.24 | D7: COMPANY TARGET | E7: Management's own model: >$80M adj. EBITDA by 2028 = 24%. Held flat after that.
B8: Years to reach the target margin | C8: 2 | D8: COMPANY TARGET | E8: Target year 2028 is about 2 years after the Jun-2026 starting point. Straight-line from LTM margin.
B9: FCF conversion (FCF / adj. EBITDA) | C9: =Inputs!B39 -> 0.87671233 | D9: CALCULATED | E9: FY2025 actual (a full year, so Q1 prepayment timing evens out). Held flat.
B10: Discount rate (required return per year) | C10: 0.1 | D10: CONVENTION | E10: Standard starting rate for the project. CAPM cross-check below. Sensitivity tab covers 8-12%.
B11: Terminal growth rate (after Year 10) | C11: 0.025 | D11: CONVENTION | E11: About the Bank of Canada 2% inflation target plus modest real growth. Must stay below the discount rate.
B12: Gross margin (display only) | C12: =Inputs!B16 -> 0.794 | D12: REPORTED | E12: Q2-2026
B14: Net ARR lost from existing customers per year = 1 - NRR | C14: =1-C5 -> 0.01
B16: CAPM cross-check (not used in the model)
B17: Risk-free rate (Canada 10-year) | C17: =Inputs!B20 -> 0.0399
B18: Beta (sources disagree: 0.73 Yahoo 5y monthly, ~1.0 Google) | C18: 1 | D18: REPORTED RANGE
B19: Equity risk premium | C19: 0.05 | D19: CONVENTION
B20: CAPM cost of equity = risk-free + beta x premium | C20: =C17+C18*C19 -> 0.0899 | E20: About 9% - so the 10% used in the model is slightly conservative (a higher rate gives a lower value).

Sheet ARR Model
A1: ARR Model - 10-year forecast (US$ m)
A2: Year | B2: 0 | C2: =B2+1 -> 1 | D2: =C2+1 -> 2 | E2: =D2+1 -> 3 | F2: =E2+1 -> 4 | G2: =F2+1 -> 5 | H2: =G2+1 -> 6 | I2: =H2+1 -> 7 | J2: =I2+1 -> 8 | ... L2: =K2+1 -> 10
A3: Period | B3: LTM Jun-26 | C3: ="Yr "&C2 -> Yr 1 | D3: ="Yr "&D2 -> Yr 2 | E3: ="Yr "&E2 -> Yr 3 | F3: ="Yr "&F2 -> Yr 4 | G3: ="Yr "&G2 -> Yr 5 | H3: ="Yr "&H2 -> Yr 6 | I3: ="Yr "&I2 -> Yr 7 | J3: ="Yr "&J2 -> Yr 8 | ... L3: ="Yr "&L2 -> Yr 10
A5: Drivers
A6: Progress to target margin (0% = today, 100% = target) | C6: =MIN(C$2/Assumptions!$C$8,1) -> 0.5 | D6: =MIN(D$2/Assumptions!$C$8,1) -> 1 | E6: =MIN(E$2/Assumptions!$C$8,1) -> 1 | F6: =MIN(F$2/Assumptions!$C$8,1) -> 1 | G6: =MIN(G$2/Assumptions!$C$8,1) -> 1 | H6: =MIN(H$2/Assumptions!$C$8,1) -> 1 | I6: =MIN(I$2/Assumptions!$C$8,1) -> 1 | J6: =MIN(J$2/Assumptions!$C$8,1) -> 1 | ... L6: =MIN(L$2/Assumptions!$C$8,1) -> 1
A7: Adj. EBITDA margin | B7: =Inputs!B35 -> 0.18501352 | C7: =Inputs!$B$35+(Assumptions!$C$7-Inputs!$B$35)*C6 -> 0.21250676 | D7: =Inputs!$B$35+(Assumptions!$C$7-Inputs!$B$35)*D6 -> 0.24 | E7: =Inputs!$B$35+(Assumptions!$C$7-Inputs!$B$35)*E6 -> 0.24 | F7: =Inputs!$B$35+(Assumptions!$C$7-Inputs!$B$35)*F6 -> 0.24 | G7: =Inputs!$B$35+(Assumptions!$C$7-Inputs!$B$35)*G6 -> 0.24 | H7: =Inputs!$B$35+(Assumptions!$C$7-Inputs!$B$35)*H6 -> 0.24 | I7: =Inputs!$B$35+(Assumptions!$C$7-Inputs!$B$35)*I6 -> 0.24 | J7: =Inputs!$B$35+(Assumptions!$C$7-Inputs!$B$35)*J6 -> 0.24 | ... L7: =Inputs!$B$35+(Assumptions!$C$7-Inputs!$B$35)*L6 -> 0.24
A8: FCF conversion (FCF / adj. EBITDA) | B8: =Inputs!B39 -> 0.87671233 | C8: =Assumptions!$C$9 -> 0.87671233 | D8: =Assumptions!$C$9 -> 0.87671233 | E8: =Assumptions!$C$9 -> 0.87671233 | F8: =Assumptions!$C$9 -> 0.87671233 | G8: =Assumptions!$C$9 -> 0.87671233 | H8: =Assumptions!$C$9 -> 0.87671233 | I8: =Assumptions!$C$9 -> 0.87671233 | J8: =Assumptions!$C$9 -> 0.87671233 | ... L8: =Assumptions!$C$9 -> 0.87671233
A9: FCF margin (EBITDA margin x conversion) | C9: =C7*C8 -> 0.1863073 | D9: =D7*D8 -> 0.21041096 | E9: =E7*E8 -> 0.21041096 | F9: =F7*F8 -> 0.21041096 | G9: =G7*G8 -> 0.21041096 | H9: =H7*H8 -> 0.21041096 | I9: =I7*I8 -> 0.21041096 | J9: =J7*J8 -> 0.21041096 | ... L9: =L7*L8 -> 0.21041096
A11: ARR bridge (Starting ARR x NRR + new-customer ARR = Ending ARR)
A12: Starting ARR | C12: =B15 -> 255.1 | D12: =C15 -> 276.88 | E12: =D15 -> 298.4422 | F12: =E15 -> 319.78878 | G12: =F15 -> 340.92189 | H12: =G15 -> 361.84367 | I12: =H15 -> 382.55623 | J12: =I15 -> 403.06167 | ... L12: =K15 -> 443.45943
A13: (+) New-customer ARR | C13: =Assumptions!$C$6 -> 24.331 | D13: =Assumptions!$C$6 -> 24.331 | E13: =Assumptions!$C$6 -> 24.331 | F13: =Assumptions!$C$6 -> 24.331 | G13: =Assumptions!$C$6 -> 24.331 | H13: =Assumptions!$C$6 -> 24.331 | I13: =Assumptions!$C$6 -> 24.331 | J13: =Assumptions!$C$6 -> 24.331 | ... L13: =Assumptions!$C$6 -> 24.331
A14: (+/-) Existing customers: Starting ARR x (NRR - 1) | C14: =C12*(Assumptions!$C$5-1) -> -2.551 | D14: =D12*(Assumptions!$C$5-1) -> -2.7688 | E14: =E12*(Assumptions!$C$5-1) -> -2.984422 | F14: =F12*(Assumptions!$C$5-1) -> -3.1978878 | G14: =G12*(Assumptions!$C$5-1) -> -3.4092189 | H14: =H12*(Assumptions!$C$5-1) -> -3.6184367 | I14: =I12*(Assumptions!$C$5-1) -> -3.8255623 | J14: =J12*(Assumptions!$C$5-1) -> -4.0306167 | ... L14: =L12*(Assumptions!$C$5-1) -> -4.4345943
A15: Ending ARR | B15: =Inputs!B40 -> 255.1 | C15: =SUM(C12:C14) -> 276.88 | D15: =SUM(D12:D14) -> 298.4422 | E15: =SUM(E12:E14) -> 319.78878 | F15: =SUM(F12:F14) -> 340.92189 | G15: =SUM(G12:G14) -> 361.84367 | H15: =SUM(H12:H14) -> 382.55623 | I15: =SUM(I12:I14) -> 403.06167 | J15: =SUM(J12:J14) -> 423.36206 | ... L15: =SUM(L12:L14) -> 463.35584
A16: ARR growth (%) | C16: =C15/B15-1 -> 0.085378283 | D16: =D15/C15-1 -> 0.077875614 | E16: =E15/D15-1 -> 0.071526674 | F16: =F15/E15-1 -> 0.066084596 | G16: =G15/F15-1 -> 0.061368254 | H16: =H15/G15-1 -> 0.057241745 | I16: =I15/H15-1 -> 0.053601107 | J16: =J15/I15-1 -> 0.050365452 | ... L16: =L15/K15-1 -> 0.044866349
A18: Revenue to free cash flow
A19: Revenue (average ARR x revenue per $ of ARR) | B19: =Inputs!B32 -> 258.9 | C19: =AVERAGE(B15,C15)*Inputs!$B$44 -> 282.11721 | D19: =AVERAGE(C15,D15)*Inputs!$B$44 -> 305.10225 | E19: =AVERAGE(D15,E15)*Inputs!$B$44 -> 327.85744 | F19: =AVERAGE(E15,F15)*Inputs!$B$44 -> 350.38507 | G19: =AVERAGE(F15,G15)*Inputs!$B$44 -> 372.68743 | H19: =AVERAGE(G15,H15)*Inputs!$B$44 -> 394.76677 | I19: =AVERAGE(H15,I15)*Inputs!$B$44 -> 416.62531 | J19: =AVERAGE(I15,J15)*Inputs!$B$44 -> 438.26527 | ... L19: =AVERAGE(K15,L15)*Inputs!$B$44 -> 480.89815
A20: Revenue growth (%) | C20: =C19/B19-1 -> 0.089676362 | D20: =D19/C19-1 -> 0.081473364 | E20: =E19/D19-1 -> 0.07458217 | F20: =F19/E19-1 -> 0.068711682 | G20: =G19/F19-1 -> 0.063650998 | H20: =H19/G19-1 -> 0.059243575 | I20: =I19/H19-1 -> 0.055370777 | J20: =J19/I19-1 -> 0.051941052 | ... L20: =L19/K19-1 -> 0.046138433
A21: Gross profit | C21: =C19*Assumptions!$C$12 -> 224.00106 | D21: =D19*Assumptions!$C$12 -> 242.25119 | E21: =E19*Assumptions!$C$12 -> 260.3188 | F21: =F19*Assumptions!$C$12 -> 278.20575 | G21: =G19*Assumptions!$C$12 -> 295.91382 | H21: =H19*Assumptions!$C$12 -> 313.44481 | I21: =I19*Assumptions!$C$12 -> 330.8005 | J21: =J19*Assumptions!$C$12 -> 347.98262 | ... L21: =L19*Assumptions!$C$12 -> 381.83313
A22: (-) Operating expenses (S&M, R&D, G&A) | C22: =C23-C21 -> -164.04925 | D22: =D23-D21 -> -169.02665 | E22: =E23-E21 -> -181.63302 | F22: =F23-F21 -> -194.11333 | G22: =G23-G21 -> -206.46884 | H22: =H23-H21 -> -218.70079 | I22: =I23-I21 -> -230.81042 | J22: =J23-J21 -> -242.79896 | ... L22: =L23-L21 -> -266.41757
A23: Adjusted EBITDA | B23: =Inputs!B33 -> 47.9 | C23: =C19*C7 -> 59.951814 | D23: =D19*D7 -> 73.22454 | E23: =E19*E7 -> 78.685785 | F23: =F19*F7 -> 84.092417 | G23: =G19*G7 -> 89.444983 | H23: =H19*H7 -> 94.744024 | I23: =I19*I7 -> 99.990074 | J23: =J19*J7 -> 105.18366 | ... L23: =L19*L7 -> 115.41556
A24: (-) Cash taxes, capex, working capital & other | C24: =-C23*(1-C8) -> -7.3913195 | D24: =-D23*(1-D8) -> -9.027683 | E24: =-E23*(1-E8) -> -9.7009871 | F24: =-F23*(1-F8) -> -10.367558 | G24: =-G23*(1-G8) -> -11.027464 | H24: =-H23*(1-H8) -> -11.68077 | I24: =-I23*(1-I8) -> -12.327543 | J24: =-J23*(1-J8) -> -12.967849 | ... L24: =-L23*(1-L8) -> -14.229315
A25: Free cash flow | B25: =Inputs!B34 -> 48.7 | C25: =C23+C24 -> 52.560495 | D25: =D23+D24 -> 64.196857 | E25: =E23+E24 -> 68.984797 | F25: =F23+F24 -> 73.724859 | G25: =G23+G24 -> 78.41752 | H25: =H23+H24 -> 83.063254 | I25: =I23+I24 -> 87.662531 | J25: =J23+J24 -> 92.215815 | ... L25: =L23+L24 -> 101.18624

Sheet DCF
A1: DCF - what the future cash is worth today
A3: Year | C3: ='ARR Model'!C2 -> 1 | D3: ='ARR Model'!D2 -> 2 | E3: ='ARR Model'!E2 -> 3 | F3: ='ARR Model'!F2 -> 4 | G3: ='ARR Model'!G2 -> 5 | H3: ='ARR Model'!H2 -> 6 | I3: ='ARR Model'!I2 -> 7 | J3: ='ARR Model'!J2 -> 8 | ... L3: ='ARR Model'!L2 -> 10
A4: Free cash flow (US$ m) | C4: ='ARR Model'!C25 -> 52.560495 | D4: ='ARR Model'!D25 -> 64.196857 | E4: ='ARR Model'!E25 -> 68.984797 | F4: ='ARR Model'!F25 -> 73.724859 | G4: ='ARR Model'!G25 -> 78.41752 | H4: ='ARR Model'!H25 -> 83.063254 | I4: ='ARR Model'!I25 -> 87.662531 | J4: ='ARR Model'!J25 -> 92.215815 | ... L4: ='ARR Model'!L25 -> 101.18624
A5: Discount factor = 1 / (1 + discount rate)^year | C5: =1/(1+Assumptions!$C$10)^C3 -> 0.90909091 | D5: =1/(1+Assumptions!$C$10)^D3 -> 0.82644628 | E5: =1/(1+Assumptions!$C$10)^E3 -> 0.7513148 | F5: =1/(1+Assumptions!$C$10)^F3 -> 0.68301346 | G5: =1/(1+Assumptions!$C$10)^G3 -> 0.62092132 | H5: =1/(1+Assumptions!$C$10)^H3 -> 0.56447393 | I5: =1/(1+Assumptions!$C$10)^I3 -> 0.51315812 | J5: =1/(1+Assumptions!$C$10)^J3 -> 0.46650738 | ... L5: =1/(1+Assumptions!$C$10)^L3 -> 0.38554329
A6: Present value of FCF | C6: =C4*C5 -> 47.782268 | D6: =D4*D5 -> 53.055253 | E6: =E4*E5 -> 51.829299 | F6: =F4*F5 -> 50.355071 | G6: =G4*G5 -> 48.69111 | H6: =H4*H5 -> 46.887041 | I6: =I4*I5 -> 44.984739 | J6: =J4*J5 -> 43.019358 | ... L6: =L4*L5 -> 39.011676
A8: Sum of PV of FCF, Years 1-10 | C8: =SUM(C6:L6) -> 466.63605
A9: Terminal value at Year 10 | C9: =L4*(1+Assumptions!C11)/(Assumptions!C10-Assumptions!C11) -> 1382.8786 | D9: FCF Year 11 / (discount rate - growth)
A10: PV of terminal value | C10: =C9*L5 -> 533.15957
A11: Enterprise value (US$ m) | C11: =C8+C10 -> 999.79562
A12: (+) Cash (after buyback) | C12: =Inputs!B13 -> 43.2167
A13: (-) Debt | C13: =-Inputs!B14 -> -88
A14: Equity value (US$ m) | C14: =SUM(C11:C13) -> 955.01232
A15: Shares outstanding (m) | C15: =Inputs!B9 -> 24.960754
A16: Value per share (US$) | C16: =C14/C15 -> 38.260556
A17: USD/CAD | C17: =Inputs!B6 -> 1.3991
A18: Model value per share (C$) | C18: =C16*C17 -> 53.530345 | D18: At reported NRR unless you change Assumptions!C5
A19: Market price today (C$) | C19: =Inputs!B5 -> 33.22
A20: Upside / (downside) vs. market | C20: =C18/C19-1 -> 0.61138906
A21: Terminal value as % of enterprise value | C21: =C10/C11 -> 0.53326856
A22: GOAL SEEK TARGET -> model price (C$) | C22: =C18 -> 53.530345 | D22: Set C22 to the market price by changing Assumptions!C5

Sheet Sensitivity
A1: Sensitivity - model share price (C$): NRR x discount rate
A2: Green = at or above today's market price. Red = below. Blue headers are editable.
A3: Market price (C$): | B3: =Inputs!B5 -> 33.22
A5: NRR ↓ / Discount rate → | B5: 0.08 | C5: 0.09 | D5: 0.1 | E5: 0.11 | F5: 0.12
A6: 0.8 | B6: =(SUMPRODUCT($M22:$V22,'ARR Model'!$C$9:$L$9,1/(1+B$5)^'ARR Model'!$C$2:$L$2)+$V22*'ARR Model'!$L$9*(1+Assumptions!$C$11)/(B$5-Assumptions!$C$11)/(1+B$5)^10+Inputs!$B$13-Inputs!$B$14)/Inputs!$B$9*Inputs!$B$6 -> 27.356038 | C6: =(SUMPRODUCT($M22:$V22,'ARR Model'!$C$9:$L$9,1/(1+C$5)^'ARR Model'!$C$2:$L$2)+$V22*'ARR Model'!$L$9*(1+Assumptions!$C$11)/(C$5-Assumptions!$C$11)/(1+C$5)^10+Inputs!$B$13-Inputs!$B$14)/Inputs!$B$9*Inputs!$B$6 -> 23.363713 | D6: =(SUMPRODUCT($M22:$V22,'ARR Model'!$C$9:$L$9,1/(1+D$5)^'ARR Model'!$C$2:$L$2)+$V22*'ARR Model'!$L$9*(1+Assumptions!$C$11)/(D$5-Assumptions!$C$11)/(1+D$5)^10+Inputs!$B$13-Inputs!$B$14)/Inputs!$B$9*Inputs!$B$6 -> 20.406977 | E6: =(SUMPRODUCT($M22:$V22,'ARR Model'!$C$9:$L$9,1/(1+E$5)^'ARR Model'!$C$2:$L$2)+$V22*'ARR Model'!$L$9*(1+Assumptions!$C$11)/(E$5-Assumptions!$C$11)/(1+E$5)^10+Inputs!$B$13-Inputs!$B$14)/Inputs!$B$9*Inputs!$B$6 -> 18.122133 | F6: =(SUMPRODUCT($M22:$V22,'ARR Model'!$C$9:$L$9,1/(1+F$5)^'ARR Model'!$C$2:$L$2)+$V22*'ARR Model'!$L$9*(1+Assumptions!$C$11)/(F$5-Assumptions!$C$11)/(1+F$5)^10+Inputs!$B$13-Inputs!$B$14)/Inputs!$B$9*Inputs!$B$6 -> 16.298485
A7: 0.85 | B7: =(SUMPRODUCT($M23:$V23,'ARR Model'!$C$9:$L$9,1/(1+B$5)^'ARR Model'!$C$2:$L$2)+$V23*'ARR Model'!$L$9*(1+Assumptions!$C$11)/(B$5-Assumptions!$C$11)/(1+B$5)^10+Inputs!$B$13-Inputs!$B$14)/Inputs!$B$9*Inputs!$B$6 -> 34.687053 | C7: =(SUMPRODUCT($M23:$V23,'ARR Model'!$C$9:$L$9,1/(1+C$5)^'ARR Model'!$C$2:$L$2)+$V23*'ARR Model'!$L$9*(1+Assumptions!$C$11)/(C$5-Assumptions!$C$11)/(1+C$5)^10+Inputs!$B$13-Inputs!$B$14)/Inputs!$B$9*Inputs!$B$6 -> 29.465444 | D7: =(SUMPRODUCT($M23:$V23,'ARR Model'!$C$9:$L$9,1/(1+D$5)^'ARR Model'!$C$2:$L$2)+$V23*'ARR Model'!$L$9*(1+Assumptions!$C$11)/(D$5-Assumptions!$C$11)/(1+D$5)^10+Inputs!$B$13-Inputs!$B$14)/Inputs!$B$9*Inputs!$B$6 -> 25.610272 | E7: =(SUMPRODUCT($M23:$V23,'ARR Model'!$C$9:$L$9,1/(1+E$5)^'ARR Model'!$C$2:$L$2)+$V23*'ARR Model'!$L$9*(1+Assumptions!$C$11)/(E$5-Assumptions!$C$11)/(1+E$5)^10+Inputs!$B$13-Inputs!$B$14)/Inputs!$B$9*Inputs!$B$6 -> 22.640951 | F7: =(SUMPRODUCT($M23:$V23,'ARR Model'!$C$9:$L$9,1/(1+F$5)^'ARR Model'!$C$2:$L$2)+$V23*'ARR Model'!$L$9*(1+Assumptions!$C$11)/(F$5-Assumptions!$C$11)/(1+F$5)^10+Inputs!$B$13-Inputs!$B$14)/Inputs!$B$9*Inputs!$B$6 -> 20.279115
A8: 0.9 | B8: =(SUMPRODUCT($M24:$V24,'ARR Model'!$C$9:$L$9,1/(1+B$5)^'ARR Model'!$C$2:$L$2)+$V24*'ARR Model'!$L$9*(1+Assumptions!$C$11)/(B$5-Assumptions!$C$11)/(1+B$5)^10+Inputs!$B$13-Inputs!$B$14)/Inputs!$B$9*Inputs!$B$6 -> 44.968814 | C8: =(SUMPRODUCT($M24:$V24,'ARR Model'!$C$9:$L$9,1/(1+C$5)^'ARR Model'!$C$2:$L$2)+$V24*'ARR Model'!$L$9*(1+Assumptions!$C$11)/(C$5-Assumptions!$C$11)/(1+C$5)^10+Inputs!$B$13-Inputs!$B$14)/Inputs!$B$9*Inputs!$B$6 -> 37.951706 | D8: =(SUMPRODUCT($M24:$V24,'ARR Model'!$C$9:$L$9,1/(1+D$5)^'ARR Model'!$C$2:$L$2)+$V24*'ARR Model'!$L$9*(1+Assumptions!$C$11)/(D$5-Assumptions!$C$11)/(1+D$5)^10+Inputs!$B$13-Inputs!$B$14)/Inputs!$B$9*Inputs!$B$6 -> 32.788925 | E8: =(SUMPRODUCT($M24:$V24,'ARR Model'!$C$9:$L$9,1/(1+E$5)^'ARR Model'!$C$2:$L$2)+$V24*'ARR Model'!$L$9*(1+Assumptions!$C$11)/(E$5-Assumptions!$C$11)/(1+E$5)^10+Inputs!$B$13-Inputs!$B$14)/Inputs!$B$9*Inputs!$B$6 -> 28.827162 | F8: =(SUMPRODUCT($M24:$V24,'ARR Model'!$C$9:$L$9,1/(1+F$5)^'ARR Model'!$C$2:$L$2)+$V24*'ARR Model'!$L$9*(1+Assumptions!$C$11)/(F$5-Assumptions!$C$11)/(1+F$5)^10+Inputs!$B$13-Inputs!$B$14)/Inputs!$B$9*Inputs!$B$6 -> 25.688093
A9: 0.95 | B9: =(SUMPRODUCT($M25:$V25,'ARR Model'!$C$9:$L$9,1/(1+B$5)^'ARR Model'!$C$2:$L$2)+$V25*'ARR Model'!$L$9*(1+Assumptions!$C$11)/(B$5-Assumptions!$C$11)/(1+B$5)^10+Inputs!$B$13-Inputs!$B$14)/Inputs!$B$9*Inputs!$B$6 -> 59.475558 | C9: =(SUMPRODUCT($M25:$V25,'ARR Model'!$C$9:$L$9,1/(1+C$5)^'ARR Model'!$C$2:$L$2)+$V25*'ARR Model'!$L$9*(1+Assumptions!$C$11)/(C$5-Assumptions!$C$11)/(1+C$5)^10+Inputs!$B$13-Inputs!$B$14)/Inputs!$B$9*Inputs!$B$6 -> 49.836662 | D9: =(SUMPRODUCT($M25:$V25,'ARR Model'!$C$9:$L$9,1/(1+D$5)^'ARR Model'!$C$2:$L$2)+$V25*'ARR Model'!$L$9*(1+Assumptions!$C$11)/(D$5-Assumptions!$C$11)/(1+D$5)^10+Inputs!$B$13-Inputs!$B$14)/Inputs!$B$9*Inputs!$B$6 -> 42.770377 | E9: =(SUMPRODUCT($M25:$V25,'ARR Model'!$C$9:$L$9,1/(1+E$5)^'ARR Model'!$C$2:$L$2)+$V25*'ARR Model'!$L$9*(1+Assumptions!$C$11)/(E$5-Assumptions!$C$11)/(1+E$5)^10+Inputs!$B$13-Inputs!$B$14)/Inputs!$B$9*Inputs!$B$6 -> 37.36866 | F9: =(SUMPRODUCT($M25:$V25,'ARR Model'!$C$9:$L$9,1/(1+F$5)^'ARR Model'!$C$2:$L$2)+$V25*'ARR Model'!$L$9*(1+Assumptions!$C$11)/(F$5-Assumptions!$C$11)/(1+F$5)^10+Inputs!$B$13-Inputs!$B$14)/Inputs!$B$9*Inputs!$B$6 -> 33.105803
A10: 0.99 | B10: =(SUMPRODUCT($M26:$V26,'ARR Model'!$C$9:$L$9,1/(1+B$5)^'ARR Model'!$C$2:$L$2)+$V26*'ARR Model'!$L$9*(1+Assumptions!$C$11)/(B$5-Assumptions!$C$11)/(1+B$5)^10+Inputs!$B$13-Inputs!$B$14)/Inputs!$B$9*Inputs!$B$6 -> 75.293443 | C10: =(SUMPRODUCT($M26:$V26,'ARR Model'!$C$9:$L$9,1/(1+C$5)^'ARR Model'!$C$2:$L$2)+$V26*'ARR Model'!$L$9*(1+Assumptions!$C$11)/(C$5-Assumptions!$C$11)/(1+C$5)^10+Inputs!$B$13-Inputs!$B$14)/Inputs!$B$9*Inputs!$B$6 -> 62.721269 | D10: =(SUMPRODUCT($M26:$V26,'ARR Model'!$C$9:$L$9,1/(1+D$5)^'ARR Model'!$C$2:$L$2)+$V26*'ARR Model'!$L$9*(1+Assumptions!$C$11)/(D$5-Assumptions!$C$11)/(1+D$5)^10+Inputs!$B$13-Inputs!$B$14)/Inputs!$B$9*Inputs!$B$6 -> 53.530345 | E10: =(SUMPRODUCT($M26:$V26,'ARR Model'!$C$9:$L$9,1/(1+E$5)^'ARR Model'!$C$2:$L$2)+$V26*'ARR Model'!$L$9*(1+Assumptions!$C$11)/(E$5-Assumptions!$C$11)/(1+E$5)^10+Inputs!$B$13-Inputs!$B$14)/Inputs!$B$9*Inputs!$B$6 -> 46.525459 | F10: =(SUMPRODUCT($M26:$V26,'ARR Model'!$C$9:$L$9,1/(1+F$5)^'ARR Model'!$C$2:$L$2)+$V26*'ARR Model'!$L$9*(1+Assumptions!$C$11)/(F$5-Assumptions!$C$11)/(1+F$5)^10+Inputs!$B$13-Inputs!$B$14)/Inputs!$B$9*Inputs!$B$6 -> 41.014786
A11: 1.01 | B11: =(SUMPRODUCT($M27:$V27,'ARR Model'!$C$9:$L$9,1/(1+B$5)^'ARR Model'!$C$2:$L$2)+$V27*'ARR Model'!$L$9*(1+Assumptions!$C$11)/(B$5-Assumptions!$C$11)/(1+B$5)^10+Inputs!$B$13-Inputs!$B$14)/Inputs!$B$9*Inputs!$B$6 -> 85.001022 | C11: =(SUMPRODUCT($M27:$V27,'ARR Model'!$C$9:$L$9,1/(1+C$5)^'ARR Model'!$C$2:$L$2)+$V27*'ARR Model'!$L$9*(1+Assumptions!$C$11)/(C$5-Assumptions!$C$11)/(1+C$5)^10+Inputs!$B$13-Inputs!$B$14)/Inputs!$B$9*Inputs!$B$6 -> 70.601915 | D11: =(SUMPRODUCT($M27:$V27,'ARR Model'!$C$9:$L$9,1/(1+D$5)^'ARR Model'!$C$2:$L$2)+$V27*'ARR Model'!$L$9*(1+Assumptions!$C$11)/(D$5-Assumptions!$C$11)/(1+D$5)^10+Inputs!$B$13-Inputs!$B$14)/Inputs!$B$9*Inputs!$B$6 -> 60.089523 | E11: =(SUMPRODUCT($M27:$V27,'ARR Model'!$C$9:$L$9,1/(1+E$5)^'ARR Model'!$C$2:$L$2)+$V27*'ARR Model'!$L$9*(1+Assumptions!$C$11)/(E$5-Assumptions!$C$11)/(1+E$5)^10+Inputs!$B$13-Inputs!$B$14)/Inputs!$B$9*Inputs!$B$6 -> 52.088986 | F11: =(SUMPRODUCT($M27:$V27,'ARR Model'!$C$9:$L$9,1/(1+F$5)^'ARR Model'!$C$2:$L$2)+$V27*'ARR Model'!$L$9*(1+Assumptions!$C$11)/(F$5-Assumptions!$C$11)/(1+F$5)^10+Inputs!$B$13-Inputs!$B$14)/Inputs!$B$9*Inputs!$B$6 -> 45.804571
A12: 1.05 | B12: =(SUMPRODUCT($M28:$V28,'ARR Model'!$C$9:$L$9,1/(1+B$5)^'ARR Model'!$C$2:$L$2)+$V28*'ARR Model'!$L$9*(1+Assumptions!$C$11)/(B$5-Assumptions!$C$11)/(1+B$5)^10+Inputs!$B$13-Inputs!$B$14)/Inputs!$B$9*Inputs!$B$6 -> 108.9173 | C12: =(SUMPRODUCT($M28:$V28,'ARR Model'!$C$9:$L$9,1/(1+C$5)^'ARR Model'!$C$2:$L$2)+$V28*'ARR Model'!$L$9*(1+Assumptions!$C$11)/(C$5-Assumptions!$C$11)/(1+C$5)^10+Inputs!$B$13-Inputs!$B$14)/Inputs!$B$9*Inputs!$B$6 -> 89.955679 | D12: =(SUMPRODUCT($M28:$V28,'ARR Model'!$C$9:$L$9,1/(1+D$5)^'ARR Model'!$C$2:$L$2)+$V28*'ARR Model'!$L$9*(1+Assumptions!$C$11)/(D$5-Assumptions!$C$11)/(1+D$5)^10+Inputs!$B$13-Inputs!$B$14)/Inputs!$B$9*Inputs!$B$6 -> 76.147353 | E12: =(SUMPRODUCT($M28:$V28,'ARR Model'!$C$9:$L$9,1/(1+E$5)^'ARR Model'!$C$2:$L$2)+$V28*'ARR Model'!$L$9*(1+Assumptions!$C$11)/(E$5-Assumptions!$C$11)/(1+E$5)^10+Inputs!$B$13-Inputs!$B$14)/Inputs!$B$9*Inputs!$B$6 -> 65.666965 | F12: =(SUMPRODUCT($M28:$V28,'ARR Model'!$C$9:$L$9,1/(1+F$5)^'ARR Model'!$C$2:$L$2)+$V28*'ARR Model'!$L$9*(1+Assumptions!$C$11)/(F$5-Assumptions!$C$11)/(1+F$5)^10+Inputs!$B$13-Inputs!$B$14)/Inputs!$B$9*Inputs!$B$6 -> 57.458245
A14: 99% = Docebo's reported FY2025 NRR. 101% = reported NRR excluding AWS.
A20: Engine (one row per NRR): ARR Y0-Y10, then revenue Y1-Y10
A21: NRR | B21: ARR Y0 | C21: ARR Y1 | D21: ARR Y2 | E21: ARR Y3 | F21: ARR Y4 | G21: ARR Y5 | H21: ARR Y6 | I21: ARR Y7 | J21: ARR Y8 | K21: ARR Y9 | L21: ARR Y10 | M21: Rev Y1 | N21: Rev Y2 | O21: Rev Y3 | P21: Rev Y4 | Q21: Rev Y5 | R21: Rev Y6 | S21: Rev Y7 | T21: Rev Y8 | U21: Rev Y9 | V21: Rev Y10
A22: =A6 -> 0.8 | B22: ='ARR Model'!$B$15 -> 255.1 | C22: =B22*$A22+'ARR Model'!C$13 -> 228.411 | D22: =C22*$A22+'ARR Model'!D$13 -> 207.0598 | E22: =D22*$A22+'ARR Model'!E$13 -> 189.97884 | F22: =E22*$A22+'ARR Model'!F$13 -> 176.31407 | G22: =F22*$A22+'ARR Model'!G$13 -> 165.38226 | H22: =G22*$A22+'ARR Model'!H$13 -> 156.63681 | I22: =H22*$A22+'ARR Model'!I$13 -> 149.64044 | J22: =I22*$A22+'ARR Model'!J$13 -> 144.04336 | ... L22: =K22*$A22+'ARR Model'!L$13 -> 135.98355 | M22: =AVERAGE(B22,C22)*Inputs!$B$44 -> 256.41335 | N22: =AVERAGE(C22,D22)*Inputs!$B$44 -> 230.93689 | O22: =AVERAGE(D22,E22)*Inputs!$B$44 -> 210.55572 | P22: =AVERAGE(E22,F22)*Inputs!$B$44 -> 194.25079 | Q22: =AVERAGE(F22,G22)*Inputs!$B$44 -> 181.20684 | R22: =AVERAGE(G22,H22)*Inputs!$B$44 -> 170.77168 | S22: =AVERAGE(H22,I22)*Inputs!$B$44 -> 162.42356 | T22: =AVERAGE(I22,J22)*Inputs!$B$44 -> 155.74506 | ... V22: =AVERAGE(K22,L22)*Inputs!$B$44 -> 146.12801
A23: =A7 -> 0.85 | B23: ='ARR Model'!$B$15 -> 255.1 | C23: =B23*$A23+'ARR Model'!C$13 -> 241.166 | D23: =C23*$A23+'ARR Model'!D$13 -> 229.3221 | E23: =D23*$A23+'ARR Model'!E$13 -> 219.25478 | F23: =E23*$A23+'ARR Model'!F$13 -> 210.69757 | G23: =F23*$A23+'ARR Model'!G$13 -> 203.42393 | H23: =G23*$A23+'ARR Model'!H$13 -> 197.24134 | I23: =H23*$A23+'ARR Model'!I$13 -> 191.98614 | J23: =I23*$A23+'ARR Model'!J$13 -> 187.51922 | ... L23: =K23*$A23+'ARR Model'!L$13 -> 180.49499 | M23: =AVERAGE(B23,C23)*Inputs!$B$44 -> 263.17752 | N23: =AVERAGE(C23,D23)*Inputs!$B$44 -> 249.50711 | O23: =AVERAGE(D23,E23)*Inputs!$B$44 -> 237.88725 | P23: =AVERAGE(E23,F23)*Inputs!$B$44 -> 228.01037 | Q23: =AVERAGE(F23,G23)*Inputs!$B$44 -> 219.61503 | R23: =AVERAGE(G23,H23)*Inputs!$B$44 -> 212.47898 | S23: =AVERAGE(H23,I23)*Inputs!$B$44 -> 206.41335 | T23: =AVERAGE(I23,J23)*Inputs!$B$44 -> 201.25755 | ... V23: =AVERAGE(K23,L23)*Inputs!$B$44 -> 193.15007
A24: =A8 -> 0.9 | B24: ='ARR Model'!$B$15 -> 255.1 | C24: =B24*$A24+'ARR Model'!C$13 -> 253.921 | D24: =C24*$A24+'ARR Model'!D$13 -> 252.8599 | E24: =D24*$A24+'ARR Model'!E$13 -> 251.90491 | F24: =E24*$A24+'ARR Model'!F$13 -> 251.04542 | G24: =F24*$A24+'ARR Model'!G$13 -> 250.27188 | H24: =G24*$A24+'ARR Model'!H$13 -> 249.57569 | I24: =H24*$A24+'ARR Model'!I$13 -> 248.94912 | J24: =I24*$A24+'ARR Model'!J$13 -> 248.38521 | ... L24: =K24*$A24+'ARR Model'!L$13 -> 247.42092 | M24: =AVERAGE(B24,C24)*Inputs!$B$44 -> 269.9417 | N24: =AVERAGE(C24,D24)*Inputs!$B$44 -> 268.75374 | O24: =AVERAGE(D24,E24)*Inputs!$B$44 -> 267.68457 | P24: =AVERAGE(E24,F24)*Inputs!$B$44 -> 266.72233 | Q24: =AVERAGE(F24,G24)*Inputs!$B$44 -> 265.8563 | R24: =AVERAGE(G24,H24)*Inputs!$B$44 -> 265.07688 | S24: =AVERAGE(H24,I24)*Inputs!$B$44 -> 264.37541 | T24: =AVERAGE(I24,J24)*Inputs!$B$44 -> 263.74408 | ... V24: =AVERAGE(K24,L24)*Inputs!$B$44 -> 262.6645
A25: =A9 -> 0.95 | B25: ='ARR Model'!$B$15 -> 255.1 | C25: =B25*$A25+'ARR Model'!C$13 -> 266.676 | D25: =C25*$A25+'ARR Model'!D$13 -> 277.6732 | E25: =D25*$A25+'ARR Model'!E$13 -> 288.12054 | F25: =E25*$A25+'ARR Model'!F$13 -> 298.04551 | G25: =F25*$A25+'ARR Model'!G$13 -> 307.47424 | H25: =G25*$A25+'ARR Model'!H$13 -> 316.43153 | I25: =H25*$A25+'ARR Model'!I$13 -> 324.94095 | J25: =I25*$A25+'ARR Model'!J$13 -> 333.0249 | ... L25: =K25*$A25+'ARR Model'!L$13 -> 348.00042 | M25: =AVERAGE(B25,C25)*Inputs!$B$44 -> 276.70587 | N25: =AVERAGE(C25,D25)*Inputs!$B$44 -> 288.67679 | O25: =AVERAGE(D25,E25)*Inputs!$B$44 -> 300.04916 | P25: =AVERAGE(E25,F25)*Inputs!$B$44 -> 310.85291 | Q25: =AVERAGE(F25,G25)*Inputs!$B$44 -> 321.11648 | R25: =AVERAGE(G25,H25)*Inputs!$B$44 -> 330.86686 | S25: =AVERAGE(H25,I25)*Inputs!$B$44 -> 340.12973 | T25: =AVERAGE(I25,J25)*Inputs!$B$44 -> 348.92945 | ... V25: =AVERAGE(K25,L25)*Inputs!$B$44 -> 365.23094
A26: =A10 -> 0.99 | B26: ='ARR Model'!$B$15 -> 255.1 | C26: =B26*$A26+'ARR Model'!C$13 -> 276.88 | D26: =C26*$A26+'ARR Model'!D$13 -> 298.4422 | E26: =D26*$A26+'ARR Model'!E$13 -> 319.78878 | F26: =E26*$A26+'ARR Model'!F$13 -> 340.92189 | G26: =F26*$A26+'ARR Model'!G$13 -> 361.84367 | H26: =G26*$A26+'ARR Model'!H$13 -> 382.55623 | I26: =H26*$A26+'ARR Model'!I$13 -> 403.06167 | J26: =I26*$A26+'ARR Model'!J$13 -> 423.36206 | ... L26: =K26*$A26+'ARR Model'!L$13 -> 463.35584 | M26: =AVERAGE(B26,C26)*Inputs!$B$44 -> 282.11721 | N26: =AVERAGE(C26,D26)*Inputs!$B$44 -> 305.10225 | O26: =AVERAGE(D26,E26)*Inputs!$B$44 -> 327.85744 | P26: =AVERAGE(E26,F26)*Inputs!$B$44 -> 350.38507 | Q26: =AVERAGE(F26,G26)*Inputs!$B$44 -> 372.68743 | R26: =AVERAGE(G26,H26)*Inputs!$B$44 -> 394.76677 | S26: =AVERAGE(H26,I26)*Inputs!$B$44 -> 416.62531 | T26: =AVERAGE(I26,J26)*Inputs!$B$44 -> 438.26527 | ... V26: =AVERAGE(K26,L26)*Inputs!$B$44 -> 480.89815
A27: =A11 -> 1.01 | B27: ='ARR Model'!$B$15 -> 255.1 | C27: =B27*$A27+'ARR Model'!C$13 -> 281.982 | D27: =C27*$A27+'ARR Model'!D$13 -> 309.13282 | E27: =D27*$A27+'ARR Model'!E$13 -> 336.55515 | F27: =E27*$A27+'ARR Model'!F$13 -> 364.2517 | G27: =F27*$A27+'ARR Model'!G$13 -> 392.22522 | H27: =G27*$A27+'ARR Model'!H$13 -> 420.47847 | I27: =H27*$A27+'ARR Model'!I$13 -> 449.01425 | J27: =I27*$A27+'ARR Model'!J$13 -> 477.8354 | ... L27: =K27*$A27+'ARR Model'!L$13 -> 536.3452 | M27: =AVERAGE(B27,C27)*Inputs!$B$44 -> 284.82288 | N27: =AVERAGE(C27,D27)*Inputs!$B$44 -> 313.47732 | O27: =AVERAGE(D27,E27)*Inputs!$B$44 -> 342.4183 | P27: =AVERAGE(E27,F27)*Inputs!$B$44 -> 371.6487 | Q27: =AVERAGE(F27,G27)*Inputs!$B$44 -> 401.17139 | R27: =AVERAGE(G27,H27)*Inputs!$B$44 -> 430.98932 | S27: =AVERAGE(H27,I27)*Inputs!$B$44 -> 461.10542 | T27: =AVERAGE(I27,J27)*Inputs!$B$44 -> 491.52268 | ... V27: =AVERAGE(K27,L27)*Inputs!$B$44 -> 553.27277
A28: =A12 -> 1.05 | B28: ='ARR Model'!$B$15 -> 255.1 | C28: =B28*$A28+'ARR Model'!C$13 -> 292.186 | D28: =C28*$A28+'ARR Model'!D$13 -> 331.1263 | E28: =D28*$A28+'ARR Model'!E$13 -> 372.01362 | F28: =E28*$A28+'ARR Model'!F$13 -> 414.9453 | G28: =F28*$A28+'ARR Model'!G$13 -> 460.02356 | H28: =G28*$A28+'ARR Model'!H$13 -> 507.35574 | I28: =H28*$A28+'ARR Model'!I$13 -> 557.05453 | J28: =I28*$A28+'ARR Model'!J$13 -> 609.23825 | ... L28: =K28*$A28+'ARR Model'!L$13 -> 721.56372 | M28: =AVERAGE(B28,C28)*Inputs!$B$44 -> 290.23422 | N28: =AVERAGE(C28,D28)*Inputs!$B$44 -> 330.55214 | O28: =AVERAGE(D28,E28)*Inputs!$B$44 -> 372.88596 | P28: =AVERAGE(E28,F28)*Inputs!$B$44 -> 417.33646 | Q28: =AVERAGE(F28,G28)*Inputs!$B$44 -> 464.0095 | R28: =AVERAGE(G28,H28)*Inputs!$B$44 -> 513.01618 | S28: =AVERAGE(H28,I28)*Inputs!$B$44 -> 564.4732 | T28: =AVERAGE(I28,J28)*Inputs!$B$44 -> 618.50307 | ... V28: =AVERAGE(K28,L28)*Inputs!$B$44 -> 734.80237

Sheet Red Flags
A1: Red flags - what looks sketchy about the company itself
A2: Facts only, each with its source. Interpretation is in the research report.
A4: # | B4: Flag | C4: The facts | D4: Source
A5: 1 | B5: Buyback nobody wanted | C5: Announced a US$70M share buyback at US$20.40, citing an undervalued stock; raised the price to US$25.00; only 99,332 shares (US$2.48M) were tendered. Intercap tendered 13,351 shares. | D5: Docebo SIB announcement 17-Jul-2026; price increase 21-Aug-2026; final results 11-Sep-2026
A6: 2 | B6: Planned to borrow for it | C6: The US$70M buyback was to be funded with ~US$10M cash and a US$60M draw on the credit facility. | D6: Docebo SIB announcement 17-Jul-2026
A7: 3 | B7: Debt went up fast | C7: Credit facility raised from US$50M to US$100M (Feb-2026), then to US$150M. Drew ~US$50M on 14-Jan-2026. Borrowings US$88.0M vs cash US$45.7M at 30-Jun-2026. | D7: Q1/Q2-2026 MD&A; Docebo release 17-Jul-2026
A8: 4 | B8: Growth partly bought | C8: Acquired 365Talents (France) on 20-Jan-2026 for US$61.3M (US$54.3M cash at closing). Expected ~US$9M revenue in 2026. 2026 ARR includes acquired ARR, which Docebo does not break out. | D8: Docebo acquisition release 20-Jan-2026; Q1-2026 preliminary release 21-Apr-2026
A9: 5 | B9: Controlled company | C9: Intercap owns 63.7% (15.9M shares). Outside shareholders cannot outvote it. | D9: SIB final results 11-Sep-2026
A10: 6 | B10: Insiders sold near the top | C10: In 2021 Intercap, founder Claudio Erba and CEO Alessio Artuffo sold shares at C$112.00 and US$49.67 in secondary offerings. The stock is C$33.22 today. | D10: Docebo secondary offering releases, 2021
A11: 7 | B11: Biggest customers leaving | C11: Largest OEM customer fell from 9.4% of ARR (Mar-2025) to 3.2% (Mar-2026) and 2.5% (Jun-2026). Management: AWS churn complete, Dayforce winding down. | D11: Q1-2026 preliminary release 21-Apr-2026; Q2-2026 release; Q2-2026 call
A12: 8 | B12: 'Adjusted' hides real costs | C12: Adjusted EBITDA excludes share-based pay, restructuring, acquisition compensation and transaction costs. Severance: US$5.2M in FY2025 and US$6.2M in Q1-2026 alone. | D12: Docebo MD&A (non-IFRS definitions); FY2025 and Q1-2026 financial statements
A13: 9 | B13: Cash flow swings | C13: Free cash flow was US$27.6M (42% of revenue) in Q1-2026, then US$3.1M (4.5%) in Q2-2026. | D13: Q1-2026 and Q2-2026 press releases
A14: 10 | B14: Growth slowed | C14: ARR growth fell from 17.8% (Q3-2024) to 8.4% (Q4-2025), then 9.5% (Q2-2026) including the acquisition. | D14: Q3-2024, Q4-2025 and Q2-2026 press releases

Sheet Sources
A1: Sources - every hard-coded number
A2: Open each link and tick the number. If a link fails, search the document title on Google or Business Wire.
A4: Item | B4: Value | C4: Where in this file | D4: Document | E4: Link
A5: ARR (annual recurring revenue), Q3-24 | B5: 214.1 | C5: Inputs!B23 | D5: Docebo Q3-2024 press release, 8 Nov 2024 (sec.gov 6-K docebo2024q3pr) | E5: https://www.sec.gov/Archives/edgar/data/1829959/000162828024046493/docebo2024q3pr.htm
A6: ARR (annual recurring revenue), Q4-24 | B6: 219.7 | C6: Inputs!C23 | D6: Docebo Q4/FY2024 press release, 28 Feb 2025 (sec.gov 6-K docebo2024q4pr) | E6: https://www.sec.gov/Archives/edgar/data/1829959/000162828025008862/docebo2024q4pr.htm
A7: ARR (annual recurring revenue), Q1-25 | B7: 225.1 | C7: Inputs!D23 | D7: Docebo Q1-2025 press release, 9 May 2025 (sec.gov 6-K docebo2025q1pr) | E7: https://www.sec.gov/Archives/edgar/data/1829959/000162828025024057/docebo2025q1pr.htm
A8: ARR (annual recurring revenue), Q2-25 | B8: 233.1 | C8: Inputs!E23 | D8: Docebo Q2-2025 press release, 8 Aug 2025 (sec.gov 6-K docebo2025q2pr) | E8: https://www.sec.gov/Archives/edgar/data/1829959/000162828025039119/docebo2025q2pr.htm
A9: ARR (annual recurring revenue), Q3-25 | B9: 235.6 | C9: Inputs!F23 | D9: Docebo Q3-2025 press release, 7 Nov 2025 (sec.gov 6-K docebo2025q3pr) | E9: https://www.sec.gov/Archives/edgar/data/1829959/000162828025050413/docebo2025q3pr.htm
A10: ARR (annual recurring revenue), Q4-25 | B10: 238.1 | C10: Inputs!G23 | D10: Docebo Q4/FY2025 press release, 27 Feb 2026 (sec.gov 6-K docebo2025q4pr) | E10: https://www.sec.gov/Archives/edgar/data/1829959/000162828026012570/docebo2025q4pr.htm
A11: ARR (annual recurring revenue), Q1-26 | B11: 248.9 | C11: Inputs!H23 | D11: Docebo Q1-2026 press release, 8 May 2026 (sec.gov 6-K docebo2026q1pr) | E11: https://www.sec.gov/Archives/edgar/data/0001829959/000162828026032550/docebo2026q1pr.htm
A12: ARR (annual recurring revenue), Q2-26 | B12: 255.1 | C12: Inputs!I23 | D12: Docebo Q2-2026 press release, 7 Aug 2026 (sec.gov 6-K docebo2026q2pr) | E12: https://www.sec.gov/Archives/edgar/data/1829959/000162828026054559/docebo2026q2pr.htm
A13: Total revenue, Q3-24 | B13: 55.4 | C13: Inputs!B24 | D13: Docebo Q3-2024 press release, 8 Nov 2024 (sec.gov 6-K docebo2024q3pr) | E13: https://www.sec.gov/Archives/edgar/data/1829959/000162828024046493/docebo2024q3pr.htm
A14: Total revenue, Q4-24 | B14: 57 | C14: Inputs!C24 | D14: Docebo Q4/FY2024 press release, 28 Feb 2025 (sec.gov 6-K docebo2024q4pr) | E14: https://www.sec.gov/Archives/edgar/data/1829959/000162828025008862/docebo2024q4pr.htm
A15: Total revenue, Q1-25 | B15: 57.3 | C15: Inputs!D24 | D15: Docebo Q1-2025 press release, 9 May 2025 (sec.gov 6-K docebo2025q1pr) | E15: https://www.sec.gov/Archives/edgar/data/1829959/000162828025024057/docebo2025q1pr.htm
A16: Total revenue, Q2-25 | B16: 60.7 | C16: Inputs!E24 | D16: Docebo Q2-2025 press release, 8 Aug 2025 (sec.gov 6-K docebo2025q2pr) | E16: https://www.sec.gov/Archives/edgar/data/1829959/000162828025039119/docebo2025q2pr.htm
... A38: USD/CAD, 17-Sep-2026 | B38: 1.3991 | C38: Inputs!B6 | D38: MTFX historical rates (verify: Bank of Canada daily rates) | E38: https://www.bankofcanada.ca/rates/exchange/daily-exchange-rates/
A39: Intercap shares / ownership | B39: 15.9M / 63.7% | C39: Inputs!B7:B8 | D39: Docebo SIB final results, 11-Sep-2026 | E39: https://finance.yahoo.com/markets/stocks/articles/docebo-inc-announces-final-results-110000945.html
A40: Buyback cash paid | B40: 2.4833 | C40: Inputs!B12 | D40: Docebo SIB final results, 11-Sep-2026 | E40: https://finance.yahoo.com/markets/stocks/articles/docebo-inc-announces-final-results-110000945.html
A41: Cash / borrowings, 30-Jun-2026 | B41: 45.7 / 88.0 | C41: Inputs!B11, B14 | D41: Docebo SIB + preliminary Q2-2026 release, 17-Jul-2026 | E41: https://finance.yahoo.com/markets/stocks/articles/docebo-inc-announces-substantial-issuer-103000376.html
A42: Gross margin Q2-2026 | B42: 0.794 | C42: Inputs!B16 | D42: Docebo Q2-2026 press release, 7 Aug 2026 (sec.gov 6-K docebo2026q2pr) | E42: https://www.sec.gov/Archives/edgar/data/1829959/000162828026054559/docebo2026q2pr.htm
A43: NRR FY2025 (and ex-AWS) | B43: 99% / 101% | C43: Inputs!B17:B18 | D43: Q4-2025 earnings call coverage, Globe and Mail | E43: https://www.theglobeandmail.com/investing/markets/stocks/DCBO/pressreleases/632787/docebo-earnings-call-bookings-strength-amid-cautious-outlook/
A44: EBITDA margin target 2028 | B44: 0.24 | C44: Inputs!B19 | D44: Docebo long-term model (Investing.com coverage) | E44: https://www.investing.com/news/analyst-ratings/needham-reiterates-docebo-stock-rating-on-efficiency-gains-93CH-4628763
A45: Canada 10-year yield | B45: 0.0399 | C45: Inputs!B20 | D45: Trading Economics, 29-Sep-2026 | E45: https://tradingeconomics.com/canada/government-bond-yield

Sheet Tracker
A1: Tracker - did the market's hidden bet change after news?
A2: After each earnings release: update Inputs, then add a row and PASTE AS VALUES the live results from Reverse DCF.
A4: Date | B4: Event | C4: Price C$ | D4: USD/CAD | E4: ARR US$m | F4: Reported NRR | G4: Implied NRR | H4: Model value C$ | I4: What changed / my read
A5: 2026-09-17 | B5: Baseline (after Q2-2026 results) | C5: =Inputs!B5 -> 33.22 | D5: =Inputs!B6 -> 1.3991 | E5: =Inputs!B40 -> 255.1 | F5: =Inputs!B17 -> 0.99 | G5: ='Reverse DCF'!H5 -> 0.90251822 | H5: ='Reverse DCF'!H10 -> 53.530345 | I5: Live link for now - paste as values before adding the next row.
A6: Nov-2026 | B6: Q3-2026 results (expected early Nov 2026)
